Workbook

Sheet Y26年渠道汇总
B1: Items | C1: 1月 | D1: 2月 | E1: 3月 | F1: 4月 | G1: 5月 | H1: 6月 | I1: 7月 | J1: 8月 | K1: 9月 | L1: 10月 | M1: 11月 | N1: 12月 | O1: 合计 1-12月 | P1: 费比 | Q1: 备注
B2: 退后销量 | O2: =SUM(C2:N2) -> 0
B3: 自补前GMV | C3: =C5/(1-$P$11) -> 48693750 | D3: =D5/(1-$P$11) -> 39641975 | E3: =E5/(1-$P$11) -> 39696543 | F3: =F5/(1-$P$11) -> 33168148 | G3: =G5/(1-$P$11) -> 70671341 | H3: =H5/(1-$P$11) -> 62217250 | I3: =I5/(1-$P$11) -> 40116707 | J3: =J5/(1-$P$11) -> 55324024 | ... N3: =N5/(1-$P$11) -> 49275904 | O3: =SUM(C3:N3) -> 6.1363962e+08
B4: 国补自补费用 | C4: =C3*$P$11 -> 4869375 | D4: =D3*$P$11 -> 3964197.5 | E4: =E3*$P$11 -> 3969654.3 | F4: =F3*$P$11 -> 3316814.8 | G4: =G3*$P$11 -> 7067134.1 | H4: =H3*$P$11 -> 6221725 | I4: =I3*$P$11 -> 4011670.7 | J4: =J3*$P$11 -> 5532402.4 | ... N4: =N3*$P$11 -> 4927590.4 | O4: =SUM(C4:N4) -> 61363962
B5: GMV（剔除国补的费用后） | C5: 43824375 | D5: 35677778 | E5: 35726889 | F5: 29851333 | G5: 63604207 | H5: 55995525 | I5: 36105037 | J5: 49791622 | K5: 39717110 | L5: 66929205 | M5: 50704265 | N5: 44348313 | O5: =SUM(C5:N5) -> 5.5227566e+08
B6: 退货率（发货前+后） | C6: 0.2 | D6: 0.19 | E6: 0.19 | F6: 0.19 | G6: 0.18 | H6: 0.2 | I6: 0.18 | J6: 0.18 | K6: 0.18 | L6: 0.17 | M6: 0.17 | N6: 0.17 | O6: =1-O7/O5 -> 0.1825153
B7: GSV（剔除国补费用后） | C7: =C5*(1-C6) -> 35059500 | D7: =D5*(1-D6) -> 28899000 | E7: =E5*(1-E6) -> 28938780 | F7: =F5*(1-F6) -> 24179580 | G7: =G5*(1-G6) -> 52155450 | H7: =H5*(1-H6) -> 44796420 | I7: =I5*(1-I6) -> 29606130 | J7: =J5*(1-J6) -> 40829130 | ... N7: =N5*(1-N6) -> 36809100 | O7: =SUM(C7:N7) -> 451476900
C8: =C3*(1-C6) -> 38955000 | D8: =D3*(1-D6) -> 32110000 | E8: =E3*(1-E6) -> 32154200 | F8: =F3*(1-F6) -> 26866200 | G8: =G3*(1-G6) -> 57950500 | H8: =H3*(1-H6) -> 49773800 | I8: =I3*(1-I6) -> 32895700 | J8: =J3*(1-J6) -> 45365700 | ... N8: =N3*(1-N6) -> 40899000 | O8: =SUM(C8:N8) -> 501641000 | P8: =O8/O3 -> 0.8174847
B9: 零售价（去除退货后的） | O9: =SUM(C9:N9) -> 0
B10: 合同折扣及返利 (线下） | O10: =SUM(C10:N10) -> 0 | Q10: 线下填写
B11: 国补自补 （线上） | C11: =C3*$P$11 -> 4869375 | D11: =D3*$P$11 -> 3964197.5 | E11: =E3*$P$11 -> 3969654.3 | F11: =F3*$P$11 -> 3316814.8 | G11: =G3*$P$11 -> 7067134.1 | H11: =H3*$P$11 -> 6221725 | I11: =I3*$P$11 -> 4011670.7 | J11: =J3*$P$11 -> 5532402.4 | ... N11: =N3*$P$11 -> 4927590.4 | O11: =SUM(C11:N11) -> 61363962 | P11: 0.1 | Q11: 按照全年拉平10%
B12: 红包消费券等促销折扣 | O12: =SUM(C12:N12) -> 0
B13: TTL 折扣合计 | C13: =SUM(C10:C12) -> 4869375 | D13: =SUM(D10:D12) -> 3964197.5 | E13: =SUM(E10:E12) -> 3969654.3 | F13: =SUM(F10:F12) -> 3316814.8 | G13: =SUM(G10:G12) -> 7067134.1 | H13: =SUM(H10:H12) -> 6221725 | I13: =SUM(I10:I12) -> 4011670.7 | J13: =SUM(J10:J12) -> 5532402.4 | ... N13: =SUM(N10:N12) -> 4927590.4 | O13: =SUM(C13:N13) -> 61363962
B14: GSV | C14: =C7 -> 35059500 | D14: =D7 -> 28899000 | E14: =E7 -> 28938780 | F14: =F7 -> 24179580 | G14: =G7 -> 52155450 | H14: =H7 -> 44796420 | I14: =I7 -> 29606130 | J14: =J7 -> 40829130 | ... N14: =N7 -> 36809100 | O14: =SUM(C14:N14) -> 451476900
B15: 营业收入 | C15: =+C7/1.13 -> 31026106 | D15: =+D7/1.13 -> 25574336 | E15: =+E7/1.13 -> 25609540 | F15: =+F7/1.13 -> 21397858 | G15: =+G7/1.13 -> 46155265 | H15: =+H7/1.13 -> 39642850 | I15: =+I7/1.13 -> 26200115 | J15: =+J7/1.13 -> 36131973 | ... N15: =+N7/1.13 -> 32574425 | O15: =SUM(C15:N15) -> 3.9953708e+08
B17: 标准主品配件成本 | C17: =C15*(1-C22) -> 15202792 | D17: =D15*(1-D22) -> 12275681 | E17: =E15*(1-E22) -> 12036484 | F17: =F15*(1-F22) -> 9843014.9 | G17: =G15*(1-G22) -> 20769869 | H17: =H15*(1-H22) -> 17442854 | I17: =I15*(1-I22) -> 11266049 | J17: =J15*(1-J22) -> 14814109 | ... N17: =N15*(1-N22) -> 12052537 | O17: =SUM(C17:N17) -> 1.7055677e+08 | P17: =O17/O15 -> 0.42688597
B18: 产品毛利 | C18: =C15-C17 -> 15823314 | D18: =D15-D17 -> 13298655 | E18: =E15-E17 -> 13573056 | F18: =F15-F17 -> 11554844 | G18: =G15-G17 -> 25385396 | H18: =H15-H17 -> 22199996 | I18: =I15-I17 -> 14934066 | J18: =J15-J17 -> 21317864 | ... N18: =N15-N17 -> 20521888 | O18: =SUM(C18:N18) -> 2.2898031e+08 | P18: =O18/$O$15 -> 0.57311403
B19: 头程/尾程物流/仓储费用 | C19: =C15*2.5% -> 775652.65 | D19: =D15*2.5% -> 639358.41 | E19: =E15*2.5% -> 640238.5 | F19: =F15*2.5% -> 534946.46 | G19: =G15*2.5% -> 1153881.6 | H19: =H15*2.5% -> 991071.24 | I19: =I15*2.5% -> 655002.88 | J19: =J15*2.5% -> 903299.34 | ... N19: =N15*2.5% -> 814360.62 | O19: =SUM(C19:N19) -> 9988427 | P19: 0.025 | Q19: 按照全年平均2.5%
B20: 成本合计（产品+物流） | C20: =SUM(C17,C19) -> 15978445 | D20: =SUM(D17,D19) -> 12915040 | E20: =SUM(E17,E19) -> 12676722 | F20: =SUM(F17,F19) -> 10377961 | G20: =SUM(G17,G19) -> 21923751 | H20: =SUM(H17,H19) -> 18433925 | I20: =SUM(I17,I19) -> 11921052 | J20: =SUM(J17,J19) -> 15717408 | ... N20: =SUM(N17,N19) -> 12866898 | O20: =SUM(C20:N20) -> 1.805452e+08 | P20: =O20/$O$15 -> 0.45188597
B21: 净毛利 | C21: =C15-C20 -> 15047662 | D21: =D15-D20 -> 12659296 | E21: =E15-E20 -> 12932818 | F21: =F15-F20 -> 11019897 | G21: =G15-G20 -> 24231514 | H21: =H15-H20 -> 21208925 | I21: =I15-I20 -> 14279063 | J21: =J15-J20 -> 20414565 | ... N21: =N15-N20 -> 19707527 | O21: =SUM(C21:N21) -> 2.1899188e+08 | P21: =O21/$O$15 -> 0.54811403
B22: 实际产品毛利率 | C22: 0.51 | D22: 0.52 | E22: 0.53 | F22: 0.54 | G22: 0.55 | H22: 0.56 | I22: 0.57 | J22: 0.59 | K22: 0.6 | L22: 0.61 | M22: 0.62 | N22: 0.63 | O22: =O18/$O$15 -> 0.57311403
B23: 合计毛利率 | C23: =IFERROR(1-C20/C15,0) -> 0.485 | D23: =IFERROR(1-D20/D15,0) -> 0.495 | E23: =IFERROR(1-E20/E15,0) -> 0.505 | F23: =IFERROR(1-F20/F15,0) -> 0.515 | G23: =IFERROR(1-G20/G15,0) -> 0.525 | H23: =IFERROR(1-H20/H15,0) -> 0.535 | I23: =IFERROR(1-I20/I15,0) -> 0.545 | J23: =IFERROR(1-J20/J15,0) -> 0.565 | ... O23: =IFERROR(1-O20/O15,0) -> 0.54811403
B25: 品牌及内容费用 | C25: =SUM(C26:C30) -> 3723132.7 | D25: =SUM(D26:D30) -> 1022973.5 | E25: =SUM(E26:E30) -> 2560954 | F25: =SUM(F26:F30) -> 1069892.9 | G25: =SUM(G26:G30) -> 5538631.9 | H25: =SUM(H26:H30) -> 2774999.5 | I25: =SUM(I26:I30) -> 1572006.9 | J25: =SUM(J26:J30) -> 2167918.4 | ... N25: =SUM(N26:N30) -> 1302977 | O25: =SUM(C25:N25) -> 28393104 | P25: =O25/$O$15 -> 0.071065003
B26: 展会 | O26: =SUM(C26:N26) -> 0 | P26: =O26/$O$15 -> 0
B27: 品牌营销 | O27: =SUM(C27:N27) -> 0 | P27: =O27/$O$15 -> 0
B28: 内容素材制作 | O28: =SUM(C28:N28) -> 0 | P28: =O28/$O$15 -> 0
B29: 公关费用 | O29: =SUM(C29:N29) -> 0 | P29: =O29/$O$15 -> 0
B30: 达人种草、样机及加热 | C30: =C15*C35 -> 3723132.7 | D30: =D15*D35 -> 1022973.5 | E30: =E15*E35 -> 2560954 | F30: =F15*F35 -> 1069892.9 | G30: =G15*G35 -> 5538631.9 | H30: =H15*H35 -> 2774999.5 | I30: =I15*I35 -> 1572006.9 | J30: =J15*J35 -> 2167918.4 | ... N30: =N15*N35 -> 1302977 | O30: =SUM(C30:N30) -> 28393104 | P30: =O30/$O$15 -> 0.071065003
B31: 展会(费率)
B32: 品牌营销（费率）
B33: 内容素材制作（费率）
B34: 公关费用（费率）
B35: 达人种草、样机及加热（费率） | C35: 0.12 | D35: 0.04 | E35: 0.1 | F35: 0.05 | G35: 0.12 | H35: 0.07 | I35: 0.06 | J35: 0.06 | K35: 0.03 | L35: 0.08 | M35: 0.05 | N35: 0.04
B36: 效果广告 | C36: =SUM(C37:C39) -> 6825743.4 | D36: =SUM(D37:D39) -> 5626354 | E36: =SUM(E37:E39) -> 5634098.8 | F36: =SUM(F37:F39) -> 4707528.8 | G36: =SUM(G37:G39) -> 10154158 | H36: =SUM(H37:H39) -> 8721426.9 | I36: =SUM(I37:I39) -> 5764025.3 | J36: =SUM(J37:J39) -> 7949034.2 | ... N36: =SUM(N37:N39) -> 7166373.5 | O36: =SUM(C36:N36) -> 87898158 | P36: =O36/$O$15 -> 0.22
B37: 站内投放 | C37: =C$15*C40 -> 4343654.9 | D37: =D$15*D40 -> 3580407.1 | E37: =E$15*E40 -> 3585335.6 | F37: =F$15*F40 -> 2995700.2 | G37: =G$15*G40 -> 6461737.2 | H37: =H$15*H40 -> 5549998.9 | I37: =I$15*I40 -> 3668016.1 | J37: =J$15*J40 -> 5058476.3 | ... N37: =N$15*N40 -> 4560419.5 | O37: =SUM(C37:N37) -> 55935191 | P37: =O37/$O$15 -> 0.14 | Q37: 全年平均14%
B38: 千川投放 | C38: =C$15*C41 -> 1861566.4 | D38: =D$15*D41 -> 1534460.2 | E38: =E$15*E41 -> 1536572.4 | F38: =F$15*F41 -> 1283871.5 | G38: =G$15*G41 -> 2769315.9 | H38: =H$15*H41 -> 2378571 | I38: =I$15*I41 -> 1572006.9 | J38: =J$15*J41 -> 2167918.4 | ... N38: =N$15*N41 -> 1954465.5 | O38: =SUM(C38:N38) -> 23972225 | P38: =O38/$O$15 -> 0.06 | Q38: 全年平均6%
B39: 站外投放 | C39: =C$15*C42 -> 620522.12 | D39: =D$15*D42 -> 511486.73 | E39: =E$15*E42 -> 512190.8 | F39: =F$15*F42 -> 427957.17 | G39: =G$15*G42 -> 923105.31 | H39: =H$15*H42 -> 792856.99 | I39: =I$15*I42 -> 524002.3 | J39: =J$15*J42 -> 722639.47 | ... N39: =N$15*N42 -> 651488.5 | O39: =SUM(C39:N39) -> 7990741.6 | P39: =O39/$O$15 -> 0.02 | Q39: 全年平均2%
B40: 站内投放（费率） | C40: 0.14 | D40: 0.14 | E40: 0.14 | F40: 0.14 | G40: 0.14 | H40: 0.14 | I40: 0.14 | J40: 0.14 | K40: 0.14 | L40: 0.14 | M40: 0.14 | N40: 0.14 | O40: =O37/$O$15 -> 0.14
B41: 千川投放（费率） | C41: 0.06 | D41: 0.06 | E41: 0.06 | F41: 0.06 | G41: 0.06 | H41: 0.06 | I41: 0.06 | J41: 0.06 | K41: 0.06 | L41: 0.06 | M41: 0.06 | N41: 0.06 | O41: =O38/$O$15 -> 0.06
B42: 站外投放（费率） | C42: 0.02 | D42: 0.02 | E42: 0.02 | F42: 0.02 | G42: 0.02 | H42: 0.02 | I42: 0.02 | J42: 0.02 | K42: 0.02 | L42: 0.02 | M42: 0.02 | N42: 0.02 | O42: =O39/$O$15 -> 0.02
...

Sheet 26年全渠道汇总
B1: Items | C1: 1月 | D1: 2月 | E1: 3月 | F1: 4月 | G1: 5月 | H1: 6月 | I1: 7月 | J1: 8月 | K1: 9月 | L1: 10月 | M1: 11月 | N1: 12月 | O1: 合计 1-12月 | P1: 费比 | Q1: 备注
B2: 退后销量 | C2: =淘系!C2+抖音!C2+PDD!C2+得物!C2+京东自营财经口径!C2+京东POP财经口径!C2+'视频号+官网+小程序'!C2+快手!C2+唯品会!C2+'线下门店-直营'!C2+'线下门店-经销'!C2+线下渠道!C2+淘系达播!C2+抖音达播!C2 -> 90463.684 | D2: =淘系!D2+抖音!D2+PDD!D2+得物!D2+京东自营财经口径!D2+京东POP财经口径!D2+'视频号+官网+小程序'!D2+快手!D2+唯品会!D2+'线下门店-直营'!D2+'线下门店-经销'!D2+线下渠道!D2+淘系达播!D2+抖音达播!D2 -> 81993.689 | E2: =淘系!E2+抖音!E2+PDD!E2+得物!E2+京东自营财经口径!E2+京东POP财经口径!E2+'视频号+官网+小程序'!E2+快手!E2+唯品会!E2+'线下门店-直营'!E2+'线下门店-经销'!E2+线下渠道!E2+淘系达播!E2+抖音达播!E2 -> 95977.292 | F2: =淘系!F2+抖音!F2+PDD!F2+得物!F2+京东自营财经口径!F2+京东POP财经口径!F2+'视频号+官网+小程序'!F2+快手!F2+唯品会!F2+'线下门店-直营'!F2+'线下门店-经销'!F2+线下渠道!F2+淘系达播!F2+抖音达播!F2 -> 80112.964 | G2: =淘系!G2+抖音!G2+PDD!G2+得物!G2+京东自营财经口径!G2+京东POP财经口径!G2+'视频号+官网+小程序'!G2+快手!G2+唯品会!G2+'线下门店-直营'!G2+'线下门店-经销'!G2+线下渠道!G2+淘系达播!G2+抖音达播!G2 -> 138286.3 | H2: =淘系!H2+抖音!H2+PDD!H2+得物!H2+京东自营财经口径!H2+京东POP财经口径!H2+'视频号+官网+小程序'!H2+快手!H2+唯品会!H2+'线下门店-直营'!H2+'线下门店-经销'!H2+线下渠道!H2+淘系达播!H2+抖音达播!H2 -> 121225.56 | I2: =淘系!I2+抖音!I2+PDD!I2+得物!I2+京东自营财经口径!I2+京东POP财经口径!I2+'视频号+官网+小程序'!I2+快手!I2+唯品会!I2+'线下门店-直营'!I2+'线下门店-经销'!I2+线下渠道!I2+淘系达播!I2+抖音达播!I2 -> 80120.129 | J2: =淘系!J2+抖音!J2+PDD!J2+得物!J2+京东自营财经口径!J2+京东POP财经口径!J2+'视频号+官网+小程序'!J2+快手!J2+唯品会!J2+'线下门店-直营'!J2+'线下门店-经销'!J2+线下渠道!J2+淘系达播!J2+抖音达播!J2 -> 99963.489 | ... N2: =淘系!N2+抖音!N2+PDD!N2+得物!N2+京东自营财经口径!N2+京东POP财经口径!N2+'视频号+官网+小程序'!N2+快手!N2+唯品会!N2+'线下门店-直营'!N2+'线下门店-经销'!N2+线下渠道!N2+淘系达播!N2+抖音达播!N2 -> 104902.51 | O2: =SUM(C2:N2) -> 1264551.1
B3: 自补前GMV | O3: =SUM(C3:N3) -> 0 | Q3: 渠道填写
B4: 自补前GSV | O4: =SUM(C4:N4) -> 0 | Q4: 渠道填写
B5: 国补自补费用 | C5: =淘系!C5+抖音!C5+PDD!C5+得物!C5+京东自营财经口径!C5+京东POP财经口径!C5+'视频号+官网+小程序'!C5+快手!C5+唯品会!C5+'线下门店-直营'!C5+'线下门店-经销'!C5+线下渠道!C5+淘系达播!C5+抖音达播!C5 -> 4607684.7 | D5: =淘系!D5+抖音!D5+PDD!D5+得物!D5+京东自营财经口径!D5+京东POP财经口径!D5+'视频号+官网+小程序'!D5+快手!D5+唯品会!D5+'线下门店-直营'!D5+'线下门店-经销'!D5+线下渠道!D5+淘系达播!D5+抖音达播!D5 -> 4599816.6 | E5: =淘系!E5+抖音!E5+PDD!E5+得物!E5+京东自营财经口径!E5+京东POP财经口径!E5+'视频号+官网+小程序'!E5+快手!E5+唯品会!E5+'线下门店-直营'!E5+'线下门店-经销'!E5+线下渠道!E5+淘系达播!E5+抖音达播!E5 -> 3914048.7 | F5: =淘系!F5+抖音!F5+PDD!F5+得物!F5+京东自营财经口径!F5+京东POP财经口径!F5+'视频号+官网+小程序'!F5+快手!F5+唯品会!F5+'线下门店-直营'!F5+'线下门店-经销'!F5+线下渠道!F5+淘系达播!F5+抖音达播!F5 -> 3349087.8 | G5: =淘系!G5+抖音!G5+PDD!G5+得物!G5+京东自营财经口径!G5+京东POP财经口径!G5+'视频号+官网+小程序'!G5+快手!G5+唯品会!G5+'线下门店-直营'!G5+'线下门店-经销'!G5+线下渠道!G5+淘系达播!G5+抖音达播!G5 -> 7313638.2 | H5: =淘系!H5+抖音!H5+PDD!H5+得物!H5+京东自营财经口径!H5+京东POP财经口径!H5+'视频号+官网+小程序'!H5+快手!H5+唯品会!H5+'线下门店-直营'!H5+'线下门店-经销'!H5+线下渠道!H5+淘系达播!H5+抖音达播!H5 -> 6508325.2 | I5: =淘系!I5+抖音!I5+PDD!I5+得物!I5+京东自营财经口径!I5+京东POP财经口径!I5+'视频号+官网+小程序'!I5+快手!I5+唯品会!I5+'线下门店-直营'!I5+'线下门店-经销'!I5+线下渠道!I5+淘系达播!I5+抖音达播!I5 -> 4346063.5 | J5: =淘系!J5+抖音!J5+PDD!J5+得物!J5+京东自营财经口径!J5+京东POP财经口径!J5+'视频号+官网+小程序'!J5+快手!J5+唯品会!J5+'线下门店-直营'!J5+'线下门店-经销'!J5+线下渠道!J5+淘系达播!J5+抖音达播!J5 -> 6197224 | ... N5: =淘系!N5+抖音!N5+PDD!N5+得物!N5+京东自营财经口径!N5+京东POP财经口径!N5+'视频号+官网+小程序'!N5+快手!N5+唯品会!N5+'线下门店-直营'!N5+'线下门店-经销'!N5+线下渠道!N5+淘系达播!N5+抖音达播!N5 -> 5803843.5 | O5: =SUM(C5:N5) -> 66408445 | Q5: 渠道填写
B6: GMV（国补后） | C6: =淘系!C6+抖音!C6+PDD!C6+得物!C6+京东自营财经口径!C6+京东POP财经口径!C6+'视频号+官网+小程序'!C6+快手!C6+唯品会!C6+'线下门店-直营'!C6++'线下门店-经销'!C6+线下渠道!C6+淘系达播!C6+抖音达播!C6 -> 38655631 | D6: =淘系!D6+抖音!D6+PDD!D6+得物!D6+京东自营财经口径!D6+京东POP财经口径!D6+'视频号+官网+小程序'!D6+快手!D6+唯品会!D6+'线下门店-直营'!D6++'线下门店-经销'!D6+线下渠道!D6+淘系达播!D6+抖音达播!D6 -> 38582248 | E6: =淘系!E6+抖音!E6+PDD!E6+得物!E6+京东自营财经口径!E6+京东POP财经口径!E6+'视频号+官网+小程序'!E6+快手!E6+唯品会!E6+'线下门店-直营'!E6++'线下门店-经销'!E6+线下渠道!E6+淘系达播!E6+抖音达播!E6 -> 32900883 | F6: =淘系!F6+抖音!F6+PDD!F6+得物!F6+京东自营财经口径!F6+京东POP财经口径!F6+'视频号+官网+小程序'!F6+快手!F6+唯品会!F6+'线下门店-直营'!F6++'线下门店-经销'!F6+线下渠道!F6+淘系达播!F6+抖音达播!F6 -> 27774427 | G6: =淘系!G6+抖音!G6+PDD!G6+得物!G6+京东自营财经口径!G6+京东POP财经口径!G6+'视频号+官网+小程序'!G6+快手!G6+唯品会!G6+'线下门店-直营'!G6++'线下门店-经销'!G6+线下渠道!G6+淘系达播!G6+抖音达播!G6 -> 60823575 | H6: =淘系!H6+抖音!H6+PDD!H6+得物!H6+京东自营财经口径!H6+京东POP财经口径!H6+'视频号+官网+小程序'!H6+快手!H6+唯品会!H6+'线下门店-直营'!H6++'线下门店-经销'!H6+线下渠道!H6+淘系达播!H6+抖音达播!H6 -> 54131266 | I6: =淘系!I6+抖音!I6+PDD!I6+得物!I6+京东自营财经口径!I6+京东POP财经口径!I6+'视频号+官网+小程序'!I6+快手!I6+唯品会!I6+'线下门店-直营'!I6++'线下门店-经销'!I6+线下渠道!I6+淘系达播!I6+抖音达播!I6 -> 37710759 | J6: =淘系!J6+抖音!J6+PDD!J6+得物!J6+京东自营财经口径!J6+京东POP财经口径!J6+'视频号+官网+小程序'!J6+快手!J6+唯品会!J6+'线下门店-直营'!J6++'线下门店-经销'!J6+线下渠道!J6+淘系达播!J6+抖音达播!J6 -> 53940593 | ... N6: =淘系!N6+抖音!N6+PDD!N6+得物!N6+京东自营财经口径!N6+京东POP财经口径!N6+'视频号+官网+小程序'!N6+快手!N6+唯品会!N6+'线下门店-直营'!N6++'线下门店-经销'!N6+线下渠道!N6+淘系达播!N6+抖音达播!N6 -> 51587222 | O6: =SUM(C6:N6) -> 5.7138404e+08 | Q6: 渠道填写
B7: 退货率（发货前+后） | C7: =1-C8/C6 -> 0.19274148 | D7: =1-D8/D6 -> 0.19111768 | E7: =1-E8/E6 -> 0.18967141 | F7: =1-F8/F6 -> 0.16821472 | G7: =1-G8/G6 -> 0.20600984 | H7: =1-H8/H6 -> 0.1885906 | I7: =1-I8/I6 -> 0.18659903 | J7: =1-J8/J6 -> 0.21274421 | ... O7: =1-O8/O6 -> 0.20097971 | Q7: 渠道填写
B8: GSV（国补后） | C8: =淘系!C8+抖音!C8+PDD!C8+得物!C8+京东自营财经口径!C8+京东POP财经口径!C8+'视频号+官网+小程序'!C8+快手!C8+唯品会!C8+'线下门店-直营'!C8++'线下门店-经销'!C8+线下渠道!C8+淘系达播!C8+抖音达播!C8 -> 31205088 | D8: =淘系!D8+抖音!D8+PDD!D8+得物!D8+京东自营财经口径!D8+京东POP财经口径!D8+'视频号+官网+小程序'!D8+快手!D8+唯品会!D8+'线下门店-直营'!D8++'线下门店-经销'!D8+线下渠道!D8+淘系达播!D8+抖音达播!D8 -> 31208498 | E8: =淘系!E8+抖音!E8+PDD!E8+得物!E8+京东自营财经口径!E8+京东POP财经口径!E8+'视频号+官网+小程序'!E8+快手!E8+唯品会!E8+'线下门店-直营'!E8++'线下门店-经销'!E8+线下渠道!E8+淘系达播!E8+抖音达播!E8 -> 26660526 | F8: =淘系!F8+抖音!F8+PDD!F8+得物!F8+京东自营财经口径!F8+京东POP财经口径!F8+'视频号+官网+小程序'!F8+快手!F8+唯品会!F8+'线下门店-直营'!F8++'线下门店-经销'!F8+线下渠道!F8+淘系达播!F8+抖音达播!F8 -> 23102360 | G8: =淘系!G8+抖音!G8+PDD!G8+得物!G8+京东自营财经口径!G8+京东POP财经口径!G8+'视频号+官网+小程序'!G8+快手!G8+唯品会!G8+'线下门店-直营'!G8++'线下门店-经销'!G8+线下渠道!G8+淘系达播!G8+抖音达播!G8 -> 48293320 | H8: =淘系!H8+抖音!H8+PDD!H8+得物!H8+京东自营财经口径!H8+京东POP财经口径!H8+'视频号+官网+小程序'!H8+快手!H8+唯品会!H8+'线下门店-直营'!H8++'线下门店-经销'!H8+线下渠道!H8+淘系达播!H8+抖音达播!H8 -> 43922618 | I8: =淘系!I8+抖音!I8+PDD!I8+得物!I8+京东自营财经口径!I8+京东POP财经口径!I8+'视频号+官网+小程序'!I8+快手!I8+唯品会!I8+'线下门店-直营'!I8++'线下门店-经销'!I8+线下渠道!I8+淘系达播!I8+抖音达播!I8 -> 30673968 | J8: =淘系!J8+抖音!J8+PDD!J8+得物!J8+京东自营财经口径!J8+京东POP财经口径!J8+'视频号+官网+小程序'!J8+快手!J8+唯品会!J8+'线下门店-直营'!J8++'线下门店-经销'!J8+线下渠道!J8+淘系达播!J8+抖音达播!J8 -> 42465045 | ... N8: =淘系!N8+抖音!N8+PDD!N8+得物!N8+京东自营财经口径!N8+京东POP财经口径!N8+'视频号+官网+小程序'!N8+快手!N8+唯品会!N8+'线下门店-直营'!N8++'线下门店-经销'!N8+线下渠道!N8+淘系达播!N8+抖音达播!N8 -> 42115074 | O8: =SUM(C8:N8) -> 4.5654745e+08 | Q8: 渠道填写
B10: 零售价（去除退货后的） | C10: =淘系!C10+抖音!C10+PDD!C10+得物!C10+京东自营财经口径!C10+京东POP财经口径!C10+'视频号+官网+小程序'!C10+快手!C10+唯品会!C10+'线下门店-直营'!C10++'线下门店-经销'!C10+线下渠道!C10+淘系达播!C10+抖音达播!C10 -> 43169030 | D10: =淘系!D10+抖音!D10+PDD!D10+得物!D10+京东自营财经口径!D10+京东POP财经口径!D10+'视频号+官网+小程序'!D10+快手!D10+唯品会!D10+'线下门店-直营'!D10++'线下门店-经销'!D10+线下渠道!D10+淘系达播!D10+抖音达播!D10 -> 41319765 | E10: =淘系!E10+抖音!E10+PDD!E10+得物!E10+京东自营财经口径!E10+京东POP财经口径!E10+'视频号+官网+小程序'!E10+快手!E10+唯品会!E10+'线下门店-直营'!E10++'线下门店-经销'!E10+线下渠道!E10+淘系达播!E10+抖音达播!E10 -> 34649173 | F10: =淘系!F10+抖音!F10+PDD!F10+得物!F10+京东自营财经口径!F10+京东POP财经口径!F10+'视频号+官网+小程序'!F10+快手!F10+唯品会!F10+'线下门店-直营'!F10++'线下门店-经销'!F10+线下渠道!F10+淘系达播!F10+抖音达播!F10 -> 30349389 | G10: =淘系!G10+抖音!G10+PDD!G10+得物!G10+京东自营财经口径!G10+京东POP财经口径!G10+'视频号+官网+小程序'!G10+快手!G10+唯品会!G10+'线下门店-直营'!G10++'线下门店-经销'!G10+线下渠道!G10+淘系达播!G10+抖音达播!G10 -> 62773132 | H10: =淘系!H10+抖音!H10+PDD!H10+得物!H10+京东自营财经口径!H10+京东POP财经口径!H10+'视频号+官网+小程序'!H10+快手!H10+唯品会!H10+'线下门店-直营'!H10++'线下门店-经销'!H10+线下渠道!H10+淘系达播!H10+抖音达播!H10 -> 57311536 | I10: =淘系!I10+抖音!I10+PDD!I10+得物!I10+京东自营财经口径!I10+京东POP财经口径!I10+'视频号+官网+小程序'!I10+快手!I10+唯品会!I10+'线下门店-直营'!I10++'线下门店-经销'!I10+线下渠道!I10+淘系达播!I10+抖音达播!I10 -> 40240744 | J10: =淘系!J10+抖音!J10+PDD!J10+得物!J10+京东自营财经口径!J10+京东POP财经口径!J10+'视频号+官网+小程序'!J10+快手!J10+唯品会!J10+'线下门店-直营'!J10++'线下门店-经销'!J10+线下渠道!J10+淘系达播!J10+抖音达播!J10 -> 55453830 | ... N10: =淘系!N10+抖音!N10+PDD!N10+得物!N10+京东自营财经口径!N10+京东POP财经口径!N10+'视频号+官网+小程序'!N10+快手!N10+唯品会!N10+'线下门店-直营'!N10++'线下门店-经销'!N10+线下渠道!N10+淘系达播!N10+抖音达播!N10 -> 55451705 | O10: =SUM(C10:N10) -> 5.9951799e+08 | Q10: 渠道第二次填写
B11: 合同折扣及返利 (线下） | C11: =淘系!C11+抖音!C11+PDD!C11+得物!C11+京东自营财经口径!C11+京东POP财经口径!C11+'视频号+官网+小程序'!C11+快手!C11+唯品会!C11+'线下门店-直营'!C11+'线下门店-经销'!C11+线下渠道!C11+淘系达播!C11+抖音达播!C11 -> 1195159.2 | D11: =淘系!D11+抖音!D11+PDD!D11+得物!D11+京东自营财经口径!D11+京东POP财经口径!D11+'视频号+官网+小程序'!D11+快手!D11+唯品会!D11+'线下门店-直营'!D11+'线下门店-经销'!D11+线下渠道!D11+淘系达播!D11+抖音达播!D11 -> 1300782.2 | E11: =淘系!E11+抖音!E11+PDD!E11+得物!E11+京东自营财经口径!E11+京东POP财经口径!E11+'视频号+官网+小程序'!E11+快手!E11+唯品会!E11+'线下门店-直营'!E11+'线下门店-经销'!E11+线下渠道!E11+淘系达播!E11+抖音达播!E11 -> 1017203.9 | F11: =淘系!F11+抖音!F11+PDD!F11+得物!F11+京东自营财经口径!F11+京东POP财经口径!F11+'视频号+官网+小程序'!F11+快手!F11+唯品会!F11+'线下门店-直营'!F11+'线下门店-经销'!F11+线下渠道!F11+淘系达播!F11+抖音达播!F11 -> 947622.99 | G11: =淘系!G11+抖音!G11+PDD!G11+得物!G11+京东自营财经口径!G11+京东POP财经口径!G11+'视频号+官网+小程序'!G11+快手!G11+唯品会!G11+'线下门店-直营'!G11+'线下门店-经销'!G11+线下渠道!G11+淘系达播!G11+抖音达播!G11 -> 1706368.4 | H11: =淘系!H11+抖音!H11+PDD!H11+得物!H11+京东自营财经口径!H11+京东POP财经口径!H11+'视频号+官网+小程序'!H11+快手!H11+唯品会!H11+'线下门店-直营'!H11+'线下门店-经销'!H11+线下渠道!H11+淘系达播!H11+抖音达播!H11 -> 1674116.6 | I11: =淘系!I11+抖音!I11+PDD!I11+得物!I11+京东自营财经口径!I11+京东POP财经口径!I11+'视频号+官网+小程序'!I11+快手!I11+唯品会!I11+'线下门店-直营'!I11+'线下门店-经销'!I11+线下渠道!I11+淘系达播!I11+抖音达播!I11 -> 1317289.2 | J11: =淘系!J11+抖音!J11+PDD!J11+得物!J11+京东自营财经口径!J11+京东POP财经口径!J11+'视频号+官网+小程序'!J11+快手!J11+唯品会!J11+'线下门店-直营'!J11+'线下门店-经销'!J11+线下渠道!J11+淘系达播!J11+抖音达播!J11 -> 1660136.2 | ... N11: =淘系!N11+抖音!N11+PDD!N11+得物!N11+京东自营财经口径!N11+京东POP财经口径!N11+'视频号+官网+小程序'!N11+快手!N11+唯品会!N11+'线下门店-直营'!N11+'线下门店-经销'!N11+线下渠道!N11+淘系达播!N11+抖音达播!N11 -> 2086010.3 | O11: =SUM(C11:N11) -> 18348907 | P11: =O11/O8 -> 0.040190581 | Q11: 线下渠道填写 | R11: =O11/$O$10 -> 0.030606099
B12: 国补自补 （线上） | C12: =淘系!C12+抖音!C12+PDD!C12+得物!C12+京东自营财经口径!C12+京东POP财经口径!C12+'视频号+官网+小程序'!C12+快手!C12+唯品会!C12+'线下门店-直营'!C12+'线下门店-经销'!C12+线下渠道!C12+淘系达播!C12+抖音达播!C12 -> 3374204.7 | D12: =淘系!D12+抖音!D12+PDD!D12+得物!D12+京东自营财经口径!D12+京东POP财经口径!D12+'视频号+官网+小程序'!D12+快手!D12+唯品会!D12+'线下门店-直营'!D12+'线下门店-经销'!D12+线下渠道!D12+淘系达播!D12+抖音达播!D12 -> 3225504 | E12: =淘系!E12+抖音!E12+PDD!E12+得物!E12+京东自营财经口径!E12+京东POP财经口径!E12+'视频号+官网+小程序'!E12+快手!E12+唯品会!E12+'线下门店-直营'!E12+'线下门店-经销'!E12+线下渠道!E12+淘系达播!E12+抖音达播!E12 -> 2793045.8 | F12: =淘系!F12+抖音!F12+PDD!F12+得物!F12+京东自营财经口径!F12+京东POP财经口径!F12+'视频号+官网+小程序'!F12+快手!F12+唯品会!F12+'线下门店-直营'!F12+'线下门店-经销'!F12+线下渠道!F12+淘系达播!F12+抖音达播!F12 -> 2421445.1 | G12: =淘系!G12+抖音!G12+PDD!G12+得物!G12+京东自营财经口径!G12+京东POP财经口径!G12+'视频号+官网+小程序'!G12+快手!G12+唯品会!G12+'线下门店-直营'!G12+'线下门店-经销'!G12+线下渠道!G12+淘系达播!G12+抖音达播!G12 -> 5483400.1 | H12: =淘系!H12+抖音!H12+PDD!H12+得物!H12+京东自营财经口径!H12+京东POP财经口径!H12+'视频号+官网+小程序'!H12+快手!H12+唯品会!H12+'线下门店-直营'!H12+'线下门店-经销'!H12+线下渠道!H12+淘系达播!H12+抖音达播!H12 -> 4885124.8 | I12: =淘系!I12+抖音!I12+PDD!I12+得物!I12+京东自营财经口径!I12+京东POP财经口径!I12+'视频号+官网+小程序'!I12+快手!I12+唯品会!I12+'线下门店-直营'!I12+'线下门店-经销'!I12+线下渠道!I12+淘系达播!I12+抖音达播!I12 -> 3103718.8 | J12: =淘系!J12+抖音!J12+PDD!J12+得物!J12+京东自营财经口径!J12+京东POP财经口径!J12+'视频号+官网+小程序'!J12+快手!J12+唯品会!J12+'线下门店-直营'!J12+'线下门店-经销'!J12+线下渠道!J12+淘系达播!J12+抖音达播!J12 -> 4576920.8 | ... N12: =淘系!N12+抖音!N12+PDD!N12+得物!N12+京东自营财经口径!N12+京东POP财经口径!N12+'视频号+官网+小程序'!N12+快手!N12+唯品会!N12+'线下门店-直营'!N12+'线下门店-经销'!N12+线下渠道!N12+淘系达播!N12+抖音达播!N12 -> 4234950.4 | O12: =SUM(C12:N12) -> 48800085 | P12: =O12/O8 -> 0.1068894 | Q12: 渠道填写 | R12: =O12/$O$10 -> 0.081398866
B13: 红包消费券等促销折扣 | C13: =淘系!C13+抖音!C13+PDD!C13+得物!C13+京东自营财经口径!C13+京东POP财经口径!C13+'视频号+官网+小程序'!C13+快手!C13+唯品会!C13+'线下门店-直营'!C13+'线下门店-经销'!C13+线下渠道!C13+淘系达播!C13+抖音达播!C13 -> 7394578.7 | D13: =淘系!D13+抖音!D13+PDD!D13+得物!D13+京东自营财经口径!D13+京东POP财经口径!D13+'视频号+官网+小程序'!D13+快手!D13+唯品会!D13+'线下门店-直营'!D13+'线下门店-经销'!D13+线下渠道!D13+淘系达播!D13+抖音达播!D13 -> 5584980.1 | E13: =淘系!E13+抖音!E13+PDD!E13+得物!E13+京东自营财经口径!E13+京东POP财经口径!E13+'视频号+官网+小程序'!E13+快手!E13+唯品会!E13+'线下门店-直营'!E13+'线下门店-经销'!E13+线下渠道!E13+淘系达播!E13+抖音达播!E13 -> 4178396.9 | F13: =淘系!F13+抖音!F13+PDD!F13+得物!F13+京东自营财经口径!F13+京东POP财经口径!F13+'视频号+官网+小程序'!F13+快手!F13+唯品会!F13+'线下门店-直营'!F13+'线下门店-经销'!F13+线下渠道!F13+淘系达播!F13+抖音达播!F13 -> 3877961.3 | G13: =淘系!G13+抖音!G13+PDD!G13+得物!G13+京东自营财经口径!G13+京东POP财经口径!G13+'视频号+官网+小程序'!G13+快手!G13+唯品会!G13+'线下门店-直营'!G13+'线下门店-经销'!G13+线下渠道!G13+淘系达播!G13+抖音达播!G13 -> 7290043.5 | H13: =淘系!H13+抖音!H13+PDD!H13+得物!H13+京东自营财经口径!H13+京东POP财经口径!H13+'视频号+官网+小程序'!H13+快手!H13+唯品会!H13+'线下门店-直营'!H13+'线下门店-经销'!H13+线下渠道!H13+淘系达播!H13+抖音达播!H13 -> 6829676.2 | I13: =淘系!I13+抖音!I13+PDD!I13+得物!I13+京东自营财经口径!I13+京东POP财经口径!I13+'视频号+官网+小程序'!I13+快手!I13+唯品会!I13+'线下门店-直营'!I13+'线下门店-经销'!I13+线下渠道!I13+淘系达播!I13+抖音达播!I13 -> 5145768 | J13: =淘系!J13+抖音!J13+PDD!J13+得物!J13+京东自营财经口径!J13+京东POP财经口径!J13+'视频号+官网+小程序'!J13+快手!J13+唯品会!J13+'线下门店-直营'!J13+'线下门店-经销'!J13+线下渠道!J13+淘系达播!J13+抖音达播!J13 -> 6751727.9 | ... N13: =淘系!N13+抖音!N13+PDD!N13+得物!N13+京东自营财经口径!N13+京东POP财经口径!N13+'视频号+官网+小程序'!N13+快手!N13+唯品会!N13+'线下门店-直营'!N13+'线下门店-经销'!N13+线下渠道!N13+淘系达播!N13+抖音达播!N13 -> 7015669.9 | O13: =SUM(C13:N13) -> 75821557 | P13: =O13/O8 -> 0.16607596 | Q13: 渠道填写 | R13: =O13/$O$10 -> 0.12647086
B14: TTL 折扣合计 | C14: =SUM(C11:C13) -> 11963943 | D14: =SUM(D11:D13) -> 10111266 | E14: =SUM(E11:E13) -> 7988646.6 | F14: =SUM(F11:F13) -> 7247029.4 | G14: =SUM(G11:G13) -> 14479812 | H14: =SUM(H11:H13) -> 13388918 | I14: =SUM(I11:I13) -> 9566775.9 | J14: =SUM(J11:J13) -> 12988785 | ... N14: =SUM(N11:N13) -> 13336631 | O14: =SUM(C14:N14) -> 1.4297055e+08 | P14: =O14/O8 -> 0.31315595 | R14: =O14/$O$10 -> 0.23847583
B15: GSV | C15: =C8 -> 31205088 | D15: =D8 -> 31208498 | E15: =E8 -> 26660526 | F15: =F8 -> 23102360 | G15: =G8 -> 48293320 | H15: =H8 -> 43922618 | I15: =I8 -> 30673968 | J15: =J8 -> 42465045 | ... N15: =N8 -> 42115074 | O15: =SUM(C15:N15) -> 4.5654745e+08
B16: 营业收入 | C16: =+C8/1.13 -> 27615122 | D16: =+D8/1.13 -> 27618140 | E16: =+E8/1.13 -> 23593386 | F16: =+F8/1.13 -> 20444566 | G16: =+G8/1.13 -> 42737451 | H16: =+H8/1.13 -> 38869573 | I16: =+I8/1.13 -> 27145104 | J16: =+J8/1.13 -> 37579685 | ... N16: =+N8/1.13 -> 37269977 | O16: =SUM(C16:N16) -> 4.0402429e+08 | T16: =O16-淘系!O16-淘系达播!O16-抖音!O16-抖音达播!O16-快手!O16-京东POP财经口径!O16-京东自营财经口径!O16-PDD!O16-得物!O16-'视频号+官网+小程序'!O16-唯品会!O16-'线下门店-直营'!O16-'线下门店-经销'!O16-线下渠道!O16 -> 0
C17: =C14/C15 -> 0.38339718 | T17: =O17-淘系!O17-淘系达播!O17-抖音!O17-抖音达播!O17-快手!O17-京东POP财经口径!O17-京东自营财经口径!O17-PDD!O17-得物!O17-'视频号+官网+小程序'!O17-唯品会!O17-'线下门店-直营'!O17-'线下门店-经销'!O17-线下渠道!O17 -> 0
B18: 标准主品配件成本 | C18: =淘系!C18+抖音!C18+PDD!C18+得物!C18+京东自营财经口径!C18+京东POP财经口径!C18+'视频号+官网+小程序'!C18+快手!C18+唯品会!C18+'线下门店-直营'!C18+'线下门店-经销'!C18+线下渠道!C18+淘系达播!C18+抖音达播!C18 -> 13519375 | D18: =淘系!D18+抖音!D18+PDD!D18+得物!D18+京东自营财经口径!D18+京东POP财经口径!D18+'视频号+官网+小程序'!D18+快手!D18+唯品会!D18+'线下门店-直营'!D18+'线下门店-经销'!D18+线下渠道!D18+淘系达播!D18+抖音达播!D18 -> 13428662 | E18: =淘系!E18+抖音!E18+PDD!E18+得物!E18+京东自营财经口径!E18+京东POP财经口径!E18+'视频号+官网+小程序'!E18+快手!E18+唯品会!E18+'线下门店-直营'!E18+'线下门店-经销'!E18+线下渠道!E18+淘系达播!E18+抖音达播!E18 -> 11966213 | F18: =淘系!F18+抖音!F18+PDD!F18+得物!F18+京东自营财经口径!F18+京东POP财经口径!F18+'视频号+官网+小程序'!F18+快手!F18+唯品会!F18+'线下门店-直营'!F18+'线下门店-经销'!F18+线下渠道!F18+淘系达播!F18+抖音达播!F18 -> 10347617 | G18: =淘系!G18+抖音!G18+PDD!G18+得物!G18+京东自营财经口径!G18+京东POP财经口径!G18+'视频号+官网+小程序'!G18+快手!G18+唯品会!G18+'线下门店-直营'!G18+'线下门店-经销'!G18+线下渠道!G18+淘系达播!G18+抖音达播!G18 -> 19576713 | H18: =淘系!H18+抖音!H18+PDD!H18+得物!H18+京东自营财经口径!H18+京东POP财经口径!H18+'视频号+官网+小程序'!H18+快手!H18+唯品会!H18+'线下门店-直营'!H18+'线下门店-经销'!H18+线下渠道!H18+淘系达播!H18+抖音达播!H18 -> 17979627 | I18: =淘系!I18+抖音!I18+PDD!I18+得物!I18+京东自营财经口径!I18+京东POP财经口径!I18+'视频号+官网+小程序'!I18+快手!I18+唯品会!I18+'线下门店-直营'!I18+'线下门店-经销'!I18+线下渠道!I18+淘系达播!I18+抖音达播!I18 -> 11695231 | J18: =淘系!J18+抖音!J18+PDD!J18+得物!J18+京东自营财经口径!J18+京东POP财经口径!J18+'视频号+官网+小程序'!J18+快手!J18+唯品会!J18+'线下门店-直营'!J18+'线下门店-经销'!J18+线下渠道!J18+淘系达播!J18+抖音达播!J18 -> 16035701 | ... N18: =淘系!N18+抖音!N18+PDD!N18+得物!N18+京东自营财经口径!N18+京东POP财经口径!N18+'视频号+官网+小程序'!N18+快手!N18+唯品会!N18+'线下门店-直营'!N18+'线下门店-经销'!N18+线下渠道!N18+淘系达播!N18+抖音达播!N18 -> 14738372 | O18: =SUM(C18:N18) -> 1.7888455e+08 | P18: =O18/O16 -> 0.44275693 | R18: Y25 Bi 成本54% | T18: =O18-淘系!O18-淘系达播!O18-抖音!O18-抖音达播!O18-快手!O18-京东POP财经口径!O18-京东自营财经口径!O18-PDD!O18-得物!O18-'视频号+官网+小程序'!O18-唯品会!O18-'线下门店-直营'!O18-'线下门店-经销'!O18-线下渠道!O18 -> 0
B19: 产品毛利 | C19: =C16-C18 -> 14095747 | D19: =D16-D18 -> 14189478 | E19: =E16-E18 -> 11627173 | F19: =F16-F18 -> 10096949 | G19: =G16-G18 -> 23160738 | H19: =H16-H18 -> 20889947 | I19: =I16-I18 -> 15449874 | J19: =J16-J18 -> 21543984 | ... N19: =N16-N18 -> 22531606 | O19: =SUM(C19:N19) -> 2.2513973e+08 | P19: =O19/$O$16 -> 0.55724307 | R19: =O16*0.12 -> 48482915 | T19: =O19-淘系!O19-淘系达播!O19-抖音!O19-抖音达播!O19-快手!O19-京东POP财经口径!O19-京东自营财经口径!O19-PDD!O19-得物!O19-'视频号+官网+小程序'!O19-唯品会!O19-'线下门店-直营'!O19-'线下门店-经销'!O19-线下渠道!O19 -> 0
B20: 头程/尾程物流/仓储费用 | C20: =C16*2.5% -> 690378.04 | D20: =D16*2.5% -> 690453.5 | E20: =E16*2.5% -> 589834.65 | F20: =F16*2.5% -> 511114.15 | G20: =G16*2.5% -> 1068436.3 | H20: =H16*2.5% -> 971739.34 | I20: =I16*2.5% -> 678627.61 | J20: =J16*2.5% -> 939492.14 | ... N20: =N16*2.5% -> 931749.43 | O20: =SUM(C20:N20) -> 10100607 | P20: 0.025 | T20: =O20-淘系!O20-淘系达播!O20-抖音!O20-抖音达播!O20-快手!O20-京东POP财经口径!O20-京东自营财经口径!O20-PDD!O20-得物!O20-'视频号+官网+小程序'!O20-唯品会!O20-'线下门店-直营'!O20-'线下门店-经销'!O20-线下渠道!O20 -> 40154.706
B21: 成本合计（产品+物流） | C21: =SUM(C18,C20) -> 14209753 | D21: =SUM(D18,D20) -> 14119115 | E21: =SUM(E18,E20) -> 12556047 | F21: =SUM(F18,F20) -> 10858731 | G21: =SUM(G18,G20) -> 20645149 | H21: =SUM(H18,H20) -> 18951366 | I21: =SUM(I18,I20) -> 12373858 | J21: =SUM(J18,J20) -> 16975194 | ... N21: =SUM(N18,N20) -> 15670121 | O21: =SUM(C21:N21) -> 1.8898516e+08 | P21: =O21/$O$16 -> 0.46775693 | T21: =O21-淘系!O21-淘系达播!O21-抖音!O21-抖音达播!O21-快手!O21-京东POP财经口径!O21-京东自营财经口径!O21-PDD!O21-得物!O21-'视频号+官网+小程序'!O21-唯品会!O21-'线下门店-直营'!O21-'线下门店-经销'!O21-线下渠道!O21 -> 40154.706
B22: 净毛利 | C22: =C16-C21 -> 13405369 | D22: =D16-D21 -> 13499025 | E22: =E16-E21 -> 11037339 | F22: =F16-F21 -> 9585835.3 | G22: =G16-G21 -> 22092302 | H22: =H16-H21 -> 19918207 | I22: =I16-I21 -> 14771246 | J22: =J16-J21 -> 20604492 | ... N22: =N16-N21 -> 21599856 | O22: =SUM(C22:N22) -> 2.1503913e+08 | P22: =O22/$O$16 -> 0.53224307 | T22: =O22-淘系!O22-淘系达播!O22-抖音!O22-抖音达播!O22-快手!O22-京东POP财经口径!O22-京东自营财经口径!O22-PDD!O22-得物!O22-'视频号+官网+小程序'!O22-唯品会!O22-'线下门店-直营'!O22-'线下门店-经销'!O22-线下渠道!O22 -> -40154.706
B23: 实际产品毛利率 | C23: =C19/C16 -> 0.5104358 | D23: =D19/D16 -> 0.51377386 | E23: =E19/E16 -> 0.49281495 | F23: =F19/F16 -> 0.49386958 | G23: =G19/G16 -> 0.54193073 | H23: =H19/H16 -> 0.537437 | I23: =I19/I16 -> 0.56915876 | J23: =J19/J16 -> 0.57328804 | ... O23: =O19/O16 -> 0.55724307 | R23: top down 毛利53% | T23: =O23-淘系!O23-淘系达播!O23-抖音!O23-抖音达播!O23-快手!O23-京东POP财经口径!O23-京东自营财经口径!O23-PDD!O23-得物!O23-'视频号+官网+小程序'!O23-唯品会!O23-'线下门店-直营'!O23-'线下门店-经销'!O23-线下渠道!O23 -> -7.2810622
B24: 合计毛利率 | C24: =IFERROR(1-C21/C16,0) -> 0.4854358 | D24: =IFERROR(1-D21/D16,0) -> 0.48877386 | E24: =IFERROR(1-E21/E16,0) -> 0.46781495 | F24: =IFERROR(1-F21/F16,0) -> 0.46886958 | G24: =IFERROR(1-G21/G16,0) -> 0.51693073 | H24: =IFERROR(1-H21/H16,0) -> 0.512437 | I24: =IFERROR(1-I21/I16,0) -> 0.54415876 | J24: =IFERROR(1-J21/J16,0) -> 0.54828804 | ... O24: =IFERROR(1-O21/O16,0) -> 0.53224307 | T24: =O24-淘系!O24-淘系达播!O24-抖音!O24-抖音达播!O24-快手!O24-京东POP财经口径!O24-京东自营财经口径!O24-PDD!O24-得物!O24-'视频号+官网+小程序'!O24-唯品会!O24-'线下门店-直营'!O24-'线下门店-经销'!O24-线下渠道!O24 -> -6.9890622
T25: =O25-淘系!O25-淘系达播!O25-抖音!O25-抖音达播!O25-快手!O25-京东POP财经口径!O25-京东自营财经口径!O25-PDD!O25-得物!O25-'视频号+官网+小程序'!O25-唯品会!O25-'线下门店-直营'!O25-'线下门店-经销'!O25-线下渠道!O25 -> 0
B26: 品牌及内容费用 | C26: =SUM(C27:C31) -> 751638.84 | D26: =SUM(D27:D31) -> 2209499.7 | E26: =SUM(E27:E31) -> 3628334.4 | F26: =SUM(F27:F31) -> 2088171 | G26: =SUM(G27:G31) -> 8100807.4 | H26: =SUM(H27:H31) -> 4791643.2 | I26: =SUM(I27:I31) -> 1089143.2 | J26: =SUM(J27:J31) -> 1639717.7 | ... N26: =SUM(N27:N31) -> 1241819.8 | O26: =SUM(C26:N26) -> 32991134 | P26: =O26/$O$16 -> 0.081656313 | T26: =O26-淘系!O26-淘系达播!O26-抖音!O26-抖音达播!O26-快手!O26-京东POP财经口径!O26-京东自营财经口径!O26-PDD!O26-得物!O26-'视频号+官网+小程序'!O26-唯品会!O26-'线下门店-直营'!O26-'线下门店-经销'!O26-线下渠道!O26 -> 0
B27: 展会 | C27: =淘系!C27+抖音!C27+PDD!C27+得物!C27+京东自营财经口径!C27+京东POP财经口径!C27+'视频号+官网+小程序'!C27+快手!C27+唯品会!C27+'线下门店-直营'!C27+'线下门店-经销'!C27+线下渠道!C27+淘系达播!C27+抖音达播!C27 -> 0 | D27: =淘系!D27+抖音!D27+PDD!D27+得物!D27+京东自营财经口径!D27+京东POP财经口径!D27+'视频号+官网+小程序'!D27+快手!D27+唯品会!D27+'线下门店-直营'!D27+'线下门店-经销'!D27+线下渠道!D27+淘系达播!D27+抖音达播!D27 -> 0 | E27: =淘系!E27+抖音!E27+PDD!E27+得物!E27+京东自营财经口径!E27+京东POP财经口径!E27+'视频号+官网+小程序'!E27+快手!E27+唯品会!E27+'线下门店-直营'!E27+'线下门店-经销'!E27+线下渠道!E27+淘系达播!E27+抖音达播!E27 -> 64814.267 | F27: =淘系!F27+抖音!F27+PDD!F27+得物!F27+京东自营财经口径!F27+京东POP财经口径!F27+'视频号+官网+小程序'!F27+快手!F27+唯品会!F27+'线下门店-直营'!F27+'线下门店-经销'!F27+线下渠道!F27+淘系达播!F27+抖音达播!F27 -> 54155.074 | G27: =淘系!G27+抖音!G27+PDD!G27+得物!G27+京东自营财经口径!G27+京东POP财经口径!G27+'视频号+官网+小程序'!G27+快手!G27+唯品会!G27+'线下门店-直营'!G27+'线下门店-经销'!G27+线下渠道!G27+淘系达播!G27+抖音达播!G27 -> 115388.16 | H27: =淘系!H27+抖音!H27+PDD!H27+得物!H27+京东自营财经口径!H27+京东POP财经口径!H27+'视频号+官网+小程序'!H27+快手!H27+唯品会!H27+'线下门店-直营'!H27+'线下门店-经销'!H27+线下渠道!H27+淘系达播!H27+抖音达播!H27 -> 101584.8 | I27: =淘系!I27+抖音!I27+PDD!I27+得物!I27+京东自营财经口径!I27+京东POP财经口径!I27+'视频号+官网+小程序'!I27+快手!I27+唯品会!I27+'线下门店-直营'!I27+'线下门店-经销'!I27+线下渠道!I27+淘系达播!I27+抖音达播!I27 -> 65500.288 | J27: =淘系!J27+抖音!J27+PDD!J27+得物!J27+京东自营财经口径!J27+京东POP财经口径!J27+'视频号+官网+小程序'!J27+快手!J27+唯品会!J27+'线下门店-直营'!J27+'线下门店-经销'!J27+线下渠道!J27+淘系达播!J27+抖音达播!J27 -> 90329.934 | ... N27: =淘系!N27+抖音!N27+PDD!N27+得物!N27+京东自营财经口径!N27+京东POP财经口径!N27+'视频号+官网+小程序'!N27+快手!N27+唯品会!N27+'线下门店-直营'!N27+'线下门店-经销'!N27+线下渠道!N27+淘系达播!N27+抖音达播!N27 -> 0 | O27: =SUM(C27:N27) -> 777231.54 | P27: =O27/$O$16 -> 0.0019237248 | T27: =O27-淘系!O27-淘系达播!O27-抖音!O27-抖音达播!O27-快手!O27-京东POP财经口径!O27-京东自营财经口径!O27-PDD!O27-得物!O27-'视频号+官网+小程序'!O27-唯品会!O27-'线下门店-直营'!O27-'线下门店-经销'!O27-线下渠道!O27 -> -1.6007107e-10
B28: 品牌营销 | C28: =淘系!C28+抖音!C28+PDD!C28+得物!C28+京东自营财经口径!C28+京东POP财经口径!C28+'视频号+官网+小程序'!C28+快手!C28+唯品会!C28+'线下门店-直营'!C28+'线下门店-经销'!C28+线下渠道!C28+淘系达播!C28+抖音达播!C28 -> 209195 | D28: =淘系!D28+抖音!D28+PDD!D28+得物!D28+京东自营财经口径!D28+京东POP财经口径!D28+'视频号+官网+小程序'!D28+快手!D28+唯品会!D28+'线下门店-直营'!D28+'线下门店-经销'!D28+线下渠道!D28+淘系达播!D28+抖音达播!D28 -> 209195 | E28: =淘系!E28+抖音!E28+PDD!E28+得物!E28+京东自营财经口径!E28+京东POP财经口径!E28+'视频号+官网+小程序'!E28+快手!E28+唯品会!E28+'线下门店-直营'!E28+'线下门店-经销'!E28+线下渠道!E28+淘系达播!E28+抖音达播!E28 -> 209195 | F28: =淘系!F28+抖音!F28+PDD!F28+得物!F28+京东自营财经口径!F28+京东POP财经口径!F28+'视频号+官网+小程序'!F28+快手!F28+唯品会!F28+'线下门店-直营'!F28+'线下门店-经销'!F28+线下渠道!F28+淘系达播!F28+抖音达播!F28 -> 274181.09 | G28: =淘系!G28+抖音!G28+PDD!G28+得物!G28+京东自营财经口径!G28+京东POP财经口径!G28+'视频号+官网+小程序'!G28+快手!G28+唯品会!G28+'线下门店-直营'!G28+'线下门店-经销'!G28+线下渠道!G28+淘系达播!G28+抖音达播!G28 -> 901523.98 | H28: =淘系!H28+抖音!H28+PDD!H28+得物!H28+京东自营财经口径!H28+京东POP财经口径!H28+'视频号+官网+小程序'!H28+快手!H28+唯品会!H28+'线下门店-直营'!H28+'线下门店-经销'!H28+线下渠道!H28+淘系达播!H28+抖音达播!H28 -> 534266.37 | I28: =淘系!I28+抖音!I28+PDD!I28+得物!I28+京东自营财经口径!I28+京东POP财经口径!I28+'视频号+官网+小程序'!I28+快手!I28+唯品会!I28+'线下门店-直营'!I28+'线下门店-经销'!I28+线下渠道!I28+淘系达播!I28+抖音达播!I28 -> 209195 | J28: =淘系!J28+抖音!J28+PDD!J28+得物!J28+京东自营财经口径!J28+京东POP财经口径!J28+'视频号+官网+小程序'!J28+快手!J28+唯品会!J28+'线下门店-直营'!J28+'线下门店-经销'!J28+线下渠道!J28+淘系达播!J28+抖音达播!J28 -> 317590.92 | ... N28: =淘系!N28+抖音!N28+PDD!N28+得物!N28+京东自营财经口径!N28+京东POP财经口径!N28+'视频号+官网+小程序'!N28+快手!N28+唯品会!N28+'线下门店-直营'!N28+'线下门店-经销'!N28+线下渠道!N28+淘系达播!N28+抖音达播!N28 -> 209195 | O28: =SUM(C28:N28) -> 4187779.5 | P28: =O28/$O$16 -> 0.010365168 | T28: =O28-淘系!O28-淘系达播!O28-抖音!O28-抖音达播!O28-快手!O28-京东POP财经口径!O28-京东自营财经口径!O28-PDD!O28-得物!O28-'视频号+官网+小程序'!O28-唯品会!O28-'线下门店-直营'!O28-'线下门店-经销'!O28-线下渠道!O28 -> 5.5297278e-10
B29: 内容素材制作 | C29: =淘系!C29+抖音!C29+PDD!C29+得物!C29+京东自营财经口径!C29+京东POP财经口径!C29+'视频号+官网+小程序'!C29+快手!C29+唯品会!C29+'线下门店-直营'!C29+'线下门店-经销'!C29+线下渠道!C29+淘系达播!C29+抖音达播!C29 -> 31801.759 | D29: =淘系!D29+抖音!D29+PDD!D29+得物!D29+京东自营财经口径!D29+京东POP财经口径!D29+'视频号+官网+小程序'!D29+快手!D29+唯品会!D29+'线下门店-直营'!D29+'线下门店-经销'!D29+线下渠道!D29+淘系达播!D29+抖音达播!D29 -> 25890.069 | E29: =淘系!E29+抖音!E29+PDD!E29+得物!E29+京东自营财经口径!E29+京东POP财经口径!E29+'视频号+官网+小程序'!E29+快手!E29+唯品会!E29+'线下门店-直营'!E29+'线下门店-经销'!E29+线下渠道!E29+淘系达播!E29+抖音达播!E29 -> 25925.707 | F29: =淘系!F29+抖音!F29+PDD!F29+得物!F29+京东自营财经口径!F29+京东POP财经口径!F29+'视频号+官网+小程序'!F29+快手!F29+唯品会!F29+'线下门店-直营'!F29+'线下门店-经销'!F29+线下渠道!F29+淘系达播!F29+抖音达播!F29 -> 108310.15 | G29: =淘系!G29+抖音!G29+PDD!G29+得物!G29+京东自营财经口径!G29+京东POP财经口径!G29+'视频号+官网+小程序'!G29+快手!G29+唯品会!G29+'线下门店-直营'!G29+'线下门店-经销'!G29+线下渠道!G29+淘系达播!G29+抖音达播!G29 -> 692328.98 | H29: =淘系!H29+抖音!H29+PDD!H29+得物!H29+京东自营财经口径!H29+京东POP财经口径!H29+'视频号+官网+小程序'!H29+快手!H29+唯品会!H29+'线下门店-直营'!H29+'线下门店-经销'!H29+线下渠道!H29+淘系达播!H29+抖音达播!H29 -> 446973.13 | I29: =淘系!I29+抖音!I29+PDD!I29+得物!I29+京东自营财经口径!I29+京东POP财经口径!I29+'视频号+官网+小程序'!I29+快手!I29+唯品会!I29+'线下门店-直营'!I29+'线下门店-经销'!I29+线下渠道!I29+淘系达播!I29+抖音达播!I29 -> 0 | J29: =淘系!J29+抖音!J29+PDD!J29+得物!J29+京东自营财经口径!J29+京东POP财经口径!J29+'视频号+官网+小程序'!J29+快手!J29+唯品会!J29+'线下门店-直营'!J29+'线下门店-经销'!J29+线下渠道!J29+淘系达播!J29+抖音达播!J29 -> 108395.92 | ... N29: =淘系!N29+抖音!N29+PDD!N29+得物!N29+京东自营财经口径!N29+京东POP财经口径!N29+'视频号+官网+小程序'!N29+快手!N29+唯品会!N29+'线下门店-直营'!N29+'线下门店-经销'!N29+线下渠道!N29+淘系达播!N29+抖音达播!N29 -> 32181.962 | O29: =SUM(C29:N29) -> 2129189.5 | P29: =O29/$O$16 -> 0.0052699542 | T29: =O29-淘系!O29-淘系达播!O29-抖音!O29-抖音达播!O29-快手!O29-京东POP财经口径!O29-京东自营财经口径!O29-PDD!O29-得物!O29-'视频号+官网+小程序'!O29-唯品会!O29-'线下门店-直营'!O29-'线下门店-经销'!O29-线下渠道!O29 -> 0
B30: 公关费用 | C30: =淘系!C30+抖音!C30+PDD!C30+得物!C30+京东自营财经口径!C30+京东POP财经口径!C30+'视频号+官网+小程序'!C30+快手!C30+唯品会!C30+'线下门店-直营'!C30+'线下门店-经销'!C30+线下渠道!C30+淘系达播!C30+抖音达播!C30 -> 31801.759 | D30: =淘系!D30+抖音!D30+PDD!D30+得物!D30+京东自营财经口径!D30+京东POP财经口径!D30+'视频号+官网+小程序'!D30+快手!D30+唯品会!D30+'线下门店-直营'!D30+'线下门店-经销'!D30+线下渠道!D30+淘系达播!D30+抖音达播!D30 -> 25890.069 | E30: =淘系!E30+抖音!E30+PDD!E30+得物!E30+京东自营财经口径!E30+京东POP财经口径!E30+'视频号+官网+小程序'!E30+快手!E30+唯品会!E30+'线下门店-直营'!E30+'线下门店-经销'!E30+线下渠道!E30+淘系达播!E30+抖音达播!E30 -> 207405.66 | F30: =淘系!F30+抖音!F30+PDD!F30+得物!F30+京东自营财经口径!F30+京东POP财经口径!F30+'视频号+官网+小程序'!F30+快手!F30+唯品会!F30+'线下门店-直营'!F30+'线下门店-经销'!F30+线下渠道!F30+淘系达播!F30+抖音达播!F30 -> 21662.029 | G30: =淘系!G30+抖音!G30+PDD!G30+得物!G30+京东自营财经口径!G30+京东POP财经口径!G30+'视频号+官网+小程序'!G30+快手!G30+唯品会!G30+'线下门店-直营'!G30+'线下门店-经销'!G30+线下渠道!G30+淘系达播!G30+抖音达播!G30 -> 138465.8 | H30: =淘系!H30+抖音!H30+PDD!H30+得物!H30+京东自营财经口径!H30+京东POP财经口径!H30+'视频号+官网+小程序'!H30+快手!H30+唯品会!H30+'线下门店-直营'!H30+'线下门店-经销'!H30+线下渠道!H30+淘系达播!H30+抖音达播!H30 -> 40633.921 | I30: =淘系!I30+抖音!I30+PDD!I30+得物!I30+京东自营财经口径!I30+京东POP财经口径!I30+'视频号+官网+小程序'!I30+快手!I30+唯品会!I30+'线下门店-直营'!I30+'线下门店-经销'!I30+线下渠道!I30+淘系达播!I30+抖音达播!I30 -> 26200.115 | J30: =淘系!J30+抖音!J30+PDD!J30+得物!J30+京东自营财经口径!J30+京东POP财经口径!J30+'视频号+官网+小程序'!J30+快手!J30+唯品会!J30+'线下门店-直营'!J30+'线下门店-经销'!J30+线下渠道!J30+淘系达播!J30+抖音达播!J30 -> 36131.973 | ... N30: =淘系!N30+抖音!N30+PDD!N30+得物!N30+京东自营财经口径!N30+京东POP财经口径!N30+'视频号+官网+小程序'!N30+快手!N30+唯品会!N30+'线下门店-直营'!N30+'线下门店-经销'!N30+线下渠道!N30+淘系达播!N30+抖音达播!N30 -> 32181.962 | O30: =SUM(C30:N30) -> 759919.23 | P30: =O30/$O$16 -> 0.0018808751 | T30: =O30-淘系!O30-淘系达播!O30-抖音!O30-抖音达播!O30-快手!O30-京东POP财经口径!O30-京东自营财经口径!O30-PDD!O30-得物!O30-'视频号+官网+小程序'!O30-唯品会!O30-'线下门店-直营'!O30-'线下门店-经销'!O30-线下渠道!O30 -> 0
B31: 达人种草、样机及加热 | C31: =淘系!C31+抖音!C31+PDD!C31+得物!C31+京东自营财经口径!C31+京东POP财经口径!C31+'视频号+官网+小程序'!C31+快手!C31+唯品会!C31+'线下门店-直营'!C31+'线下门店-经销'!C31+线下渠道!C31+淘系达播!C31+抖音达播!C31 -> 478840.32 | D31: =淘系!D31+抖音!D31+PDD!D31+得物!D31+京东自营财经口径!D31+京东POP财经口径!D31+'视频号+官网+小程序'!D31+快手!D31+唯品会!D31+'线下门店-直营'!D31+'线下门店-经销'!D31+线下渠道!D31+淘系达播!D31+抖音达播!D31 -> 1948524.6 | E31: =淘系!E31+抖音!E31+PDD!E31+得物!E31+京东自营财经口径!E31+京东POP财经口径!E31+'视频号+官网+小程序'!E31+快手!E31+唯品会!E31+'线下门店-直营'!E31+'线下门店-经销'!E31+线下渠道!E31+淘系达播!E31+抖音达播!E31 -> 3120993.8 | F31: =淘系!F31+抖音!F31+PDD!F31+得物!F31+京东自营财经口径!F31+京东POP财经口径!F31+'视频号+官网+小程序'!F31+快手!F31+唯品会!F31+'线下门店-直营'!F31+'线下门店-经销'!F31+线下渠道!F31+淘系达播!F31+抖音达播!F31 -> 1629862.7 | G31: =淘系!G31+抖音!G31+PDD!G31+得物!G31+京东自营财经口径!G31+京东POP财经口径!G31+'视频号+官网+小程序'!G31+快手!G31+唯品会!G31+'线下门店-直营'!G31+'线下门店-经销'!G31+线下渠道!G31+淘系达播!G31+抖音达播!G31 -> 6253100.5 | H31: =淘系!H31+抖音!H31+PDD!H31+得物!H31+京东自营财经口径!H31+京东POP财经口径!H31+'视频号+官网+小程序'!H31+快手!H31+唯品会!H31+'线下门店-直营'!H31+'线下门店-经销'!H31+线下渠道!H31+淘系达播!H31+抖音达播!H31 -> 3668185 | I31: =淘系!I31+抖音!I31+PDD!I31+得物!I31+京东自营财经口径!I31+京东POP财经口径!I31+'视频号+官网+小程序'!I31+快手!I31+唯品会!I31+'线下门店-直营'!I31+'线下门店-经销'!I31+线下渠道!I31+淘系达播!I31+抖音达播!I31 -> 788247.76 | J31: =淘系!J31+抖音!J31+PDD!J31+得物!J31+京东自营财经口径!J31+京东POP财经口径!J31+'视频号+官网+小程序'!J31+快手!J31+唯品会!J31+'线下门店-直营'!J31+'线下门店-经销'!J31+线下渠道!J31+淘系达播!J31+抖音达播!J31 -> 1087268.9 | ... N31: =淘系!N31+抖音!N31+PDD!N31+得物!N31+京东自营财经口径!N31+京东POP财经口径!N31+'视频号+官网+小程序'!N31+快手!N31+唯品会!N31+'线下门店-直营'!N31+'线下门店-经销'!N31+线下渠道!N31+淘系达播!N31+抖音达播!N31 -> 968260.91 | O31: =SUM(C31:N31) -> 25137014 | P31: =O31/$O$16 -> 0.062216591 | T31: =O31-淘系!O31-淘系达播!O31-抖音!O31-抖音达播!O31-快手!O31-京东POP财经口径!O31-京东自营财经口径!O31-PDD!O31-得物!O31-'视频号+官网+小程序'!O31-唯品会!O31-'线下门店-直营'!O31-'线下门店-经销'!O31-线下渠道!O31 -> 0
B32: 展会(费率) | T32: =O32-淘系!O32-淘系达播!O32-抖音!O32-抖音达播!O32-快手!O32-京东POP财经口径!O32-京东自营财经口径!O32-PDD!O32-得物!O32-'视频号+官网+小程序'!O32-唯品会!O32-'线下门店-直营'!O32-'线下门店-经销'!O32-线下渠道!O32 -> 0
B33: 品牌营销（费率） | T33: =O33-淘系!O33-淘系达播!O33-抖音!O33-抖音达播!O33-快手!O33-京东POP财经口径!O33-京东自营财经口径!O33-PDD!O33-得物!O33-'视频号+官网+小程序'!O33-唯品会!O33-'线下门店-直营'!O33-'线下门店-经销'!O33-线下渠道!O33 -> 0
B34: 内容素材制作（费率） | T34: =O34-淘系!O34-淘系达播!O34-抖音!O34-抖音达播!O34-快手!O34-京东POP财经口径!O34-京东自营财经口径!O34-PDD!O34-得物!O34-'视频号+官网+小程序'!O34-唯品会!O34-'线下门店-直营'!O34-'线下门店-经销'!O34-线下渠道!O34 -> 0
B35: 公关费用（费率） | T35: =O35-淘系!O35-淘系达播!O35-抖音!O35-抖音达播!O35-快手!O35-京东POP财经口径!O35-京东自营财经口径!O35-PDD!O35-得物!O35-'视频号+官网+小程序'!O35-唯品会!O35-'线下门店-直营'!O35-'线下门店-经销'!O35-线下渠道!O35 -> 0
B36: 达人种草、样机及加热（费率） | T36: =O36-淘系!O36-淘系达播!O36-抖音!O36-抖音达播!O36-快手!O36-京东POP财经口径!O36-京东自营财经口径!O36-PDD!O36-得物!O36-'视频号+官网+小程序'!O36-唯品会!O36-'线下门店-直营'!O36-'线下门店-经销'!O36-线下渠道!O36 -> 0
B37: 效果广告 | C37: =SUM(C38:C40) -> 5289161.1 | D37: =SUM(D38:D40) -> 6011795.3 | E37: =SUM(E38:E40) -> 4469411.7 | F37: =SUM(F38:F40) -> 3799706.2 | G37: =SUM(G38:G40) -> 9797097.2 | H37: =SUM(H38:H40) -> 8746823 | I37: =SUM(I38:I40) -> 4912801.7 | J37: =SUM(J38:J40) -> 8629549.9 | ... N37: =SUM(N38:N40) -> 6666059 | O37: =SUM(C37:N37) -> 82824979 | P37: =O37/$O$16 -> 0.205 | R37: =O16*20.5% -> 82824979 | T37: =O37-淘系!O37-淘系达播!O37-抖音!O37-抖音达播!O37-快手!O37-京东POP财经口径!O37-京东自营财经口径!O37-PDD!O37-得物!O37-'视频号+官网+小程序'!O37-唯品会!O37-'线下门店-直营'!O37-'线下门店-经销'!O37-线下渠道!O37 -> -2.3283064e-10
B38: 站内投放 | C38: =淘系!C38+抖音!C38+PDD!C38+得物!C38+京东自营财经口径!C38+京东POP财经口径!C38+'视频号+官网+小程序'!C38+快手!C38+唯品会!C38+'线下门店-直营'!C38+'线下门店-经销'!C38+线下渠道!C38+淘系达播!C38+抖音达播!C38 -> 2292019.8 | D38: =淘系!D38+抖音!D38+PDD!D38+得物!D38+京东自营财经口径!D38+京东POP财经口径!D38+'视频号+官网+小程序'!D38+快手!D38+唯品会!D38+'线下门店-直营'!D38+'线下门店-经销'!D38+线下渠道!D38+淘系达播!D38+抖音达播!D38 -> 2749177.4 | E38: =淘系!E38+抖音!E38+PDD!E38+得物!E38+京东自营财经口径!E38+京东POP财经口径!E38+'视频号+官网+小程序'!E38+快手!E38+唯品会!E38+'线下门店-直营'!E38+'线下门店-经销'!E38+线下渠道!E38+淘系达播!E38+抖音达播!E38 -> 2219902.6 | F38: =淘系!F38+抖音!F38+PDD!F38+得物!F38+京东自营财经口径!F38+京东POP财经口径!F38+'视频号+官网+小程序'!F38+快手!F38+唯品会!F38+'线下门店-直营'!F38+'线下门店-经销'!F38+线下渠道!F38+淘系达播!F38+抖音达播!F38 -> 1900622 | G38: =淘系!G38+抖音!G38+PDD!G38+得物!G38+京东自营财经口径!G38+京东POP财经口径!G38+'视频号+官网+小程序'!G38+快手!G38+唯品会!G38+'线下门店-直营'!G38+'线下门店-经销'!G38+线下渠道!G38+淘系达播!G38+抖音达播!G38 -> 4748153.5 | H38: =淘系!H38+抖音!H38+PDD!H38+得物!H38+京东自营财经口径!H38+京东POP财经口径!H38+'视频号+官网+小程序'!H38+快手!H38+唯品会!H38+'线下门店-直营'!H38+'线下门店-经销'!H38+线下渠道!H38+淘系达播!H38+抖音达播!H38 -> 4563874.8 | I38: =淘系!I38+抖音!I38+PDD!I38+得物!I38+京东自营财经口径!I38+京东POP财经口径!I38+'视频号+官网+小程序'!I38+快手!I38+唯品会!I38+'线下门店-直营'!I38+'线下门店-经销'!I38+线下渠道!I38+淘系达播!I38+抖音达播!I38 -> 2576178.9 | J38: =淘系!J38+抖音!J38+PDD!J38+得物!J38+京东自营财经口径!J38+京东POP财经口径!J38+'视频号+官网+小程序'!J38+快手!J38+唯品会!J38+'线下门店-直营'!J38+'线下门店-经销'!J38+线下渠道!J38+淘系达播!J38+抖音达播!J38 -> 4648298.8 | ... N38: =淘系!N38+抖音!N38+PDD!N38+得物!N38+京东自营财经口径!N38+京东POP财经口径!N38+'视频号+官网+小程序'!N38+快手!N38+唯品会!N38+'线下门店-直营'!N38+'线下门店-经销'!N38+线下渠道!N38+淘系达播!N38+抖音达播!N38 -> 3186379.6 | O38: =SUM(C38:N38) -> 41931094 | P38: =O38/$O$16 -> 0.1037836 | Q38: 投放填写 | R38: =O37-R37 -> -0.04135856 | T38: =O38-淘系!O38-淘系达播!O38-抖音!O38-抖音达播!O38-快手!O38-京东POP财经口径!O38-京东自营财经口径!O38-PDD!O38-得物!O38-'视频号+官网+小程序'!O38-唯品会!O38-'线下门店-直营'!O38-'线下门店-经销'!O38-线下渠道!O38 -> -1.3271347e-08
B39: 千川投放 | C39: =淘系!C39+抖音!C39+PDD!C39+得物!C39+京东自营财经口径!C39+京东POP财经口径!C39+'视频号+官网+小程序'!C39+快手!C39+唯品会!C39+'线下门店-直营'!C39+'线下门店-经销'!C39+线下渠道!C39+淘系达播!C39+抖音达播!C39 -> 2298503 | D39: =淘系!D39+抖音!D39+PDD!D39+得物!D39+京东自营财经口径!D39+京东POP财经口径!D39+'视频号+官网+小程序'!D39+快手!D39+唯品会!D39+'线下门店-直营'!D39+'线下门店-经销'!D39+线下渠道!D39+淘系达播!D39+抖音达播!D39 -> 2468200.8 | E39: =淘系!E39+抖音!E39+PDD!E39+得物!E39+京东自营财经口径!E39+京东POP财经口径!E39+'视频号+官网+小程序'!E39+快手!E39+唯品会!E39+'线下门店-直营'!E39+'线下门店-经销'!E39+线下渠道!E39+淘系达播!E39+抖音达播!E39 -> 1582066.6 | F39: =淘系!F39+抖音!F39+PDD!F39+得物!F39+京东自营财经口径!F39+京东POP财经口径!F39+'视频号+官网+小程序'!F39+快手!F39+唯品会!F39+'线下门店-直营'!F39+'线下门店-经销'!F39+线下渠道!F39+淘系达播!F39+抖音达播!F39 -> 1336204.9 | G39: =淘系!G39+抖音!G39+PDD!G39+得物!G39+京东自营财经口径!G39+京东POP财经口径!G39+'视频号+官网+小程序'!G39+快手!G39+唯品会!G39+'线下门店-直营'!G39+'线下门店-经销'!G39+线下渠道!G39+淘系达播!G39+抖音达播!G39 -> 3070752.4 | H39: =淘系!H39+抖音!H39+PDD!H39+得物!H39+京东自营财经口径!H39+京东POP财经口径!H39+'视频号+官网+小程序'!H39+快手!H39+唯品会!H39+'线下门店-直营'!H39+'线下门店-经销'!H39+线下渠道!H39+淘系达播!H39+抖音达播!H39 -> 2791593.1 | I39: =淘系!I39+抖音!I39+PDD!I39+得物!I39+京东自营财经口径!I39+京东POP财经口径!I39+'视频号+官网+小程序'!I39+快手!I39+唯品会!I39+'线下门店-直营'!I39+'线下门店-经销'!I39+线下渠道!I39+淘系达播!I39+抖音达播!I39 -> 1603445.8 | J39: =淘系!J39+抖音!J39+PDD!J39+得物!J39+京东自营财经口径!J39+京东POP财经口径!J39+'视频号+官网+小程序'!J39+快手!J39+唯品会!J39+'线下门店-直营'!J39+'线下门店-经销'!J39+线下渠道!J39+淘系达播!J39+抖音达播!J39 -> 2583206.5 | ... N39: =淘系!N39+抖音!N39+PDD!N39+得物!N39+京东自营财经口径!N39+京东POP财经口径!N39+'视频号+官网+小程序'!N39+快手!N39+唯品会!N39+'线下门店-直营'!N39+'线下门店-经销'!N39+线下渠道!N39+淘系达播!N39+抖音达播!N39 -> 2571042.5 | O39: =SUM(C39:N39) -> 27750461 | P39: =O39/$O$16 -> 0.06868513 | Q39: 投放填写 | R39: =淘系!O31+抖音!O31+京东自营财经口径!O31 -> 20683454 | T39: =O39-淘系!O39-淘系达播!O39-抖音!O39-抖音达播!O39-快手!O39-京东POP财经口径!O39-京东自营财经口径!O39-PDD!O39-得物!O39-'视频号+官网+小程序'!O39-唯品会!O39-'线下门店-直营'!O39-'线下门店-经销'!O39-线下渠道!O39 -> 0
B40: 站外投放 | C40: =淘系!C40+抖音!C40+PDD!C40+得物!C40+京东自营财经口径!C40+京东POP财经口径!C40+'视频号+官网+小程序'!C40+快手!C40+唯品会!C40+'线下门店-直营'!C40+'线下门店-经销'!C40+线下渠道!C40+淘系达播!C40+抖音达播!C40 -> 698638.3 | D40: =淘系!D40+抖音!D40+PDD!D40+得物!D40+京东自营财经口径!D40+京东POP财经口径!D40+'视频号+官网+小程序'!D40+快手!D40+唯品会!D40+'线下门店-直营'!D40+'线下门店-经销'!D40+线下渠道!D40+淘系达播!D40+抖音达播!D40 -> 794417.05 | E40: =淘系!E40+抖音!E40+PDD!E40+得物!E40+京东自营财经口径!E40+京东POP财经口径!E40+'视频号+官网+小程序'!E40+快手!E40+唯品会!E40+'线下门店-直营'!E40+'线下门店-经销'!E40+线下渠道!E40+淘系达播!E40+抖音达播!E40 -> 667442.57 | F40: =淘系!F40+抖音!F40+PDD!F40+得物!F40+京东自营财经口径!F40+京东POP财经口径!F40+'视频号+官网+小程序'!F40+快手!F40+唯品会!F40+'线下门店-直营'!F40+'线下门店-经销'!F40+线下渠道!F40+淘系达播!F40+抖音达播!F40 -> 562879.37 | G40: =淘系!G40+抖音!G40+PDD!G40+得物!G40+京东自营财经口径!G40+京东POP财经口径!G40+'视频号+官网+小程序'!G40+快手!G40+唯品会!G40+'线下门店-直营'!G40+'线下门店-经销'!G40+线下渠道!G40+淘系达播!G40+抖音达播!G40 -> 1978191.3 | H40: =淘系!H40+抖音!H40+PDD!H40+得物!H40+京东自营财经口径!H40+京东POP财经口径!H40+'视频号+官网+小程序'!H40+快手!H40+唯品会!H40+'线下门店-直营'!H40+'线下门店-经销'!H40+线下渠道!H40+淘系达播!H40+抖音达播!H40 -> 1391355.1 | I40: =淘系!I40+抖音!I40+PDD!I40+得物!I40+京东自营财经口径!I40+京东POP财经口径!I40+'视频号+官网+小程序'!I40+快手!I40+唯品会!I40+'线下门店-直营'!I40+'线下门店-经销'!I40+线下渠道!I40+淘系达播!I40+抖音达播!I40 -> 733176.96 | J40: =淘系!J40+抖音!J40+PDD!J40+得物!J40+京东自营财经口径!J40+京东POP财经口径!J40+'视频号+官网+小程序'!J40+快手!J40+唯品会!J40+'线下门店-直营'!J40+'线下门店-经销'!J40+线下渠道!J40+淘系达播!J40+抖音达播!J40 -> 1398044.6 | ... N40: =淘系!N40+抖音!N40+PDD!N40+得物!N40+京东自营财经口径!N40+京东POP财经口径!N40+'视频号+官网+小程序'!N40+快手!N40+唯品会!N40+'线下门店-直营'!N40+'线下门店-经销'!N40+线下渠道!N40+淘系达播!N40+抖音达播!N40 -> 908636.98 | O40: =SUM(C40:N40) -> 13143425 | P40: =O40/$O$16 -> 0.032531273 | Q40: 投放填写 | R40: =淘系!O31 -> 9080973.7 | S40: =R40/$R$39 -> 0.43904531 | T40: =O40-淘系!O40-淘系达播!O40-抖音!O40-抖音达播!O40-快手!O40-京东POP财经口径!O40-京东自营财经口径!O40-PDD!O40-得物!O40-'视频号+官网+小程序'!O40-唯品会!O40-'线下门店-直营'!O40-'线下门店-经销'!O40-线下渠道!O40 -> 0
B41: 站内投放（费率） | C41: =C38/C$16 -> 0.08299872 | D41: =D38/D$16 -> 0.099542454 | E41: =E38/E$16 -> 0.094090036 | F41: =F38/F$16 -> 0.092964652 | G41: =G38/G$16 -> 0.11110053 | H41: =H38/H$16 -> 0.1174151 | I41: =I38/I$16 -> 0.094903997 | J41: =J38/J$16 -> 0.1236918 | ... N41: =N38/N$16 -> 0.085494541 | O41: =O38/$O$16 -> 0.1037836 | Q41: 投放填写 | S41: =R41/$R$39 -> 0 | T41: =O41-淘系!O41-淘系达播!O41-抖音!O41-抖音达播!O41-快手!O41-京东POP财经口径!O41-京东自营财经口径!O41-PDD!O41-得物!O41-'视频号+官网+小程序'!O41-唯品会!O41-'线下门店-直营'!O41-'线下门店-经销'!O41-线下渠道!O41 -> -0.99470872
...

Sheet 26年全渠道汇总（副本计算）
B1: Items | C1: 1月 | E1: 2月 | F1: 3月 | G1: 4月 | H1: 5月 | I1: 6月 | J1: 7月 | K1: 8月 | L1: 9月 | M1: 10月 | N1: 11月 | O1: 12月 | P1: 合计 1-12月 | Q1: 费比 | R1: 备注
B2: 退后销量 | C2: =淘系!C2+抖音!C2+PDD!C2+得物!C2+京东自营财经口径!C2+京东POP财经口径!C2+'视频号+官网+小程序'!C2+快手!C2+唯品会!C2+'线下门店-直营'!C2+'线下门店-经销'!C2+线下渠道!C2+淘系达播!C2+抖音达播!C2 -> 90463.684 | E2: =淘系!D2+抖音!D2+PDD!D2+得物!D2+京东自营财经口径!D2+京东POP财经口径!D2+'视频号+官网+小程序'!D2+快手!D2+唯品会!D2+'线下门店-直营'!D2+'线下门店-经销'!D2+线下渠道!D2+淘系达播!D2+抖音达播!D2 -> 81993.689 | F2: =淘系!E2+抖音!E2+PDD!E2+得物!E2+京东自营财经口径!E2+京东POP财经口径!E2+'视频号+官网+小程序'!E2+快手!E2+唯品会!E2+'线下门店-直营'!E2+'线下门店-经销'!E2+线下渠道!E2+淘系达播!E2+抖音达播!E2 -> 95977.292 | G2: =淘系!F2+抖音!F2+PDD!F2+得物!F2+京东自营财经口径!F2+京东POP财经口径!F2+'视频号+官网+小程序'!F2+快手!F2+唯品会!F2+'线下门店-直营'!F2+'线下门店-经销'!F2+线下渠道!F2+淘系达播!F2+抖音达播!F2 -> 80112.964 | H2: =淘系!G2+抖音!G2+PDD!G2+得物!G2+京东自营财经口径!G2+京东POP财经口径!G2+'视频号+官网+小程序'!G2+快手!G2+唯品会!G2+'线下门店-直营'!G2+'线下门店-经销'!G2+线下渠道!G2+淘系达播!G2+抖音达播!G2 -> 138286.3 | I2: =淘系!H2+抖音!H2+PDD!H2+得物!H2+京东自营财经口径!H2+京东POP财经口径!H2+'视频号+官网+小程序'!H2+快手!H2+唯品会!H2+'线下门店-直营'!H2+'线下门店-经销'!H2+线下渠道!H2+淘系达播!H2+抖音达播!H2 -> 121225.56 | J2: =淘系!I2+抖音!I2+PDD!I2+得物!I2+京东自营财经口径!I2+京东POP财经口径!I2+'视频号+官网+小程序'!I2+快手!I2+唯品会!I2+'线下门店-直营'!I2+'线下门店-经销'!I2+线下渠道!I2+淘系达播!I2+抖音达播!I2 -> 80120.129 | K2: =淘系!J2+抖音!J2+PDD!J2+得物!J2+京东自营财经口径!J2+京东POP财经口径!J2+'视频号+官网+小程序'!J2+快手!J2+唯品会!J2+'线下门店-直营'!J2+'线下门店-经销'!J2+线下渠道!J2+淘系达播!J2+抖音达播!J2 -> 99963.489 | L2: =淘系!K2+抖音!K2+PDD!K2+得物!K2+京东自营财经口径!K2+京东POP财经口径!K2+'视频号+官网+小程序'!K2+快手!K2+唯品会!K2+'线下门店-直营'!K2+'线下门店-经销'!K2+线下渠道!K2+淘系达播!K2+抖音达播!K2 -> 109614.03 | ... O2: =淘系!N2+抖音!N2+PDD!N2+得物!N2+京东自营财经口径!N2+京东POP财经口径!N2+'视频号+官网+小程序'!N2+快手!N2+唯品会!N2+'线下门店-直营'!N2+'线下门店-经销'!N2+线下渠道!N2+淘系达播!N2+抖音达播!N2 -> 104902.51 | P2: =SUM(C2:O2) -> 1264551.1
B3: 自补前GMV | P3: =SUM(C3:O3) -> 0 | R3: 渠道填写
B4: 自补前GSV | P4: =SUM(C4:O4) -> 0 | R4: 渠道填写
B5: 国补自补费用 | C5: =淘系!C5+抖音!C5+PDD!C5+得物!C5+京东自营财经口径!C5+京东POP财经口径!C5+'视频号+官网+小程序'!C5+快手!C5+唯品会!C5+'线下门店-直营'!C5+'线下门店-经销'!C5+线下渠道!C5+淘系达播!C5+抖音达播!C5 -> 4607684.7 | E5: =淘系!D5+抖音!D5+PDD!D5+得物!D5+京东自营财经口径!D5+京东POP财经口径!D5+'视频号+官网+小程序'!D5+快手!D5+唯品会!D5+'线下门店-直营'!D5+'线下门店-经销'!D5+线下渠道!D5+淘系达播!D5+抖音达播!D5 -> 4599816.6 | F5: =淘系!E5+抖音!E5+PDD!E5+得物!E5+京东自营财经口径!E5+京东POP财经口径!E5+'视频号+官网+小程序'!E5+快手!E5+唯品会!E5+'线下门店-直营'!E5+'线下门店-经销'!E5+线下渠道!E5+淘系达播!E5+抖音达播!E5 -> 3914048.7 | G5: =淘系!F5+抖音!F5+PDD!F5+得物!F5+京东自营财经口径!F5+京东POP财经口径!F5+'视频号+官网+小程序'!F5+快手!F5+唯品会!F5+'线下门店-直营'!F5+'线下门店-经销'!F5+线下渠道!F5+淘系达播!F5+抖音达播!F5 -> 3349087.8 | H5: =淘系!G5+抖音!G5+PDD!G5+得物!G5+京东自营财经口径!G5+京东POP财经口径!G5+'视频号+官网+小程序'!G5+快手!G5+唯品会!G5+'线下门店-直营'!G5+'线下门店-经销'!G5+线下渠道!G5+淘系达播!G5+抖音达播!G5 -> 7313638.2 | I5: =淘系!H5+抖音!H5+PDD!H5+得物!H5+京东自营财经口径!H5+京东POP财经口径!H5+'视频号+官网+小程序'!H5+快手!H5+唯品会!H5+'线下门店-直营'!H5+'线下门店-经销'!H5+线下渠道!H5+淘系达播!H5+抖音达播!H5 -> 6508325.2 | J5: =淘系!I5+抖音!I5+PDD!I5+得物!I5+京东自营财经口径!I5+京东POP财经口径!I5+'视频号+官网+小程序'!I5+快手!I5+唯品会!I5+'线下门店-直营'!I5+'线下门店-经销'!I5+线下渠道!I5+淘系达播!I5+抖音达播!I5 -> 4346063.5 | K5: =淘系!J5+抖音!J5+PDD!J5+得物!J5+京东自营财经口径!J5+京东POP财经口径!J5+'视频号+官网+小程序'!J5+快手!J5+唯品会!J5+'线下门店-直营'!J5+'线下门店-经销'!J5+线下渠道!J5+淘系达播!J5+抖音达播!J5 -> 6197224 | L5: =淘系!K5+抖音!K5+PDD!K5+得物!K5+京东自营财经口径!K5+京东POP财经口径!K5+'视频号+官网+小程序'!K5+快手!K5+唯品会!K5+'线下门店-直营'!K5+'线下门店-经销'!K5+线下渠道!K5+淘系达播!K5+抖音达播!K5 -> 4425098.7 | ... O5: =淘系!N5+抖音!N5+PDD!N5+得物!N5+京东自营财经口径!N5+京东POP财经口径!N5+'视频号+官网+小程序'!N5+快手!N5+唯品会!N5+'线下门店-直营'!N5+'线下门店-经销'!N5+线下渠道!N5+淘系达播!N5+抖音达播!N5 -> 5803843.5 | P5: =SUM(C5:O5) -> 66408445 | R5: 渠道填写
B6: GMV（国补后） | C6: =淘系!C6+抖音!C6+PDD!C6+得物!C6+京东自营财经口径!C6+京东POP财经口径!C6+'视频号+官网+小程序'!C6+快手!C6+唯品会!C6+'线下门店-直营'!C6++'线下门店-经销'!C6+线下渠道!C6+淘系达播!C6+抖音达播!C6 -> 38655631 | E6: =淘系!D6+抖音!D6+PDD!D6+得物!D6+京东自营财经口径!D6+京东POP财经口径!D6+'视频号+官网+小程序'!D6+快手!D6+唯品会!D6+'线下门店-直营'!D6++'线下门店-经销'!D6+线下渠道!D6+淘系达播!D6+抖音达播!D6 -> 38582248 | F6: =淘系!E6+抖音!E6+PDD!E6+得物!E6+京东自营财经口径!E6+京东POP财经口径!E6+'视频号+官网+小程序'!E6+快手!E6+唯品会!E6+'线下门店-直营'!E6++'线下门店-经销'!E6+线下渠道!E6+淘系达播!E6+抖音达播!E6 -> 32900883 | G6: =淘系!F6+抖音!F6+PDD!F6+得物!F6+京东自营财经口径!F6+京东POP财经口径!F6+'视频号+官网+小程序'!F6+快手!F6+唯品会!F6+'线下门店-直营'!F6++'线下门店-经销'!F6+线下渠道!F6+淘系达播!F6+抖音达播!F6 -> 27774427 | H6: =淘系!G6+抖音!G6+PDD!G6+得物!G6+京东自营财经口径!G6+京东POP财经口径!G6+'视频号+官网+小程序'!G6+快手!G6+唯品会!G6+'线下门店-直营'!G6++'线下门店-经销'!G6+线下渠道!G6+淘系达播!G6+抖音达播!G6 -> 60823575 | I6: =淘系!H6+抖音!H6+PDD!H6+得物!H6+京东自营财经口径!H6+京东POP财经口径!H6+'视频号+官网+小程序'!H6+快手!H6+唯品会!H6+'线下门店-直营'!H6++'线下门店-经销'!H6+线下渠道!H6+淘系达播!H6+抖音达播!H6 -> 54131266 | J6: =淘系!I6+抖音!I6+PDD!I6+得物!I6+京东自营财经口径!I6+京东POP财经口径!I6+'视频号+官网+小程序'!I6+快手!I6+唯品会!I6+'线下门店-直营'!I6++'线下门店-经销'!I6+线下渠道!I6+淘系达播!I6+抖音达播!I6 -> 37710759 | K6: =淘系!J6+抖音!J6+PDD!J6+得物!J6+京东自营财经口径!J6+京东POP财经口径!J6+'视频号+官网+小程序'!J6+快手!J6+唯品会!J6+'线下门店-直营'!J6++'线下门店-经销'!J6+线下渠道!J6+淘系达播!J6+抖音达播!J6 -> 53940593 | L6: =淘系!K6+抖音!K6+PDD!K6+得物!K6+京东自营财经口径!K6+京东POP财经口径!K6+'视频号+官网+小程序'!K6+快手!K6+唯品会!K6+'线下门店-直营'!K6++'线下门店-经销'!K6+线下渠道!K6+淘系达播!K6+抖音达播!K6 -> 40234860 | ... O6: =淘系!N6+抖音!N6+PDD!N6+得物!N6+京东自营财经口径!N6+京东POP财经口径!N6+'视频号+官网+小程序'!N6+快手!N6+唯品会!N6+'线下门店-直营'!N6++'线下门店-经销'!N6+线下渠道!N6+淘系达播!N6+抖音达播!N6 -> 51587222 | P6: =SUM(C6:O6) -> 5.7138404e+08 | R6: 渠道填写
B7: 退货率（发货前+后） | C7: =1-C8/C6 -> 0.19274148 | E7: =1-E8/E6 -> 0.19111768 | F7: =1-F8/F6 -> 0.18967141 | G7: =1-G8/G6 -> 0.16821472 | H7: =1-H8/H6 -> 0.20600984 | I7: =1-I8/I6 -> 0.1885906 | J7: =1-J8/J6 -> 0.18659903 | K7: =1-K8/K6 -> 0.21274421 | L7: =1-L8/L6 -> 0.22807461 | ... P7: =1-P8/P6 -> 0.20097971 | R7: 渠道填写
B8: GSV（国补后） | C8: =淘系!C8+抖音!C8+PDD!C8+得物!C8+京东自营财经口径!C8+京东POP财经口径!C8+'视频号+官网+小程序'!C8+快手!C8+唯品会!C8+'线下门店-直营'!C8++'线下门店-经销'!C8+线下渠道!C8+淘系达播!C8+抖音达播!C8 -> 31205088 | E8: =淘系!D8+抖音!D8+PDD!D8+得物!D8+京东自营财经口径!D8+京东POP财经口径!D8+'视频号+官网+小程序'!D8+快手!D8+唯品会!D8+'线下门店-直营'!D8++'线下门店-经销'!D8+线下渠道!D8+淘系达播!D8+抖音达播!D8 -> 31208498 | F8: =淘系!E8+抖音!E8+PDD!E8+得物!E8+京东自营财经口径!E8+京东POP财经口径!E8+'视频号+官网+小程序'!E8+快手!E8+唯品会!E8+'线下门店-直营'!E8++'线下门店-经销'!E8+线下渠道!E8+淘系达播!E8+抖音达播!E8 -> 26660526 | G8: =淘系!F8+抖音!F8+PDD!F8+得物!F8+京东自营财经口径!F8+京东POP财经口径!F8+'视频号+官网+小程序'!F8+快手!F8+唯品会!F8+'线下门店-直营'!F8++'线下门店-经销'!F8+线下渠道!F8+淘系达播!F8+抖音达播!F8 -> 23102360 | H8: =淘系!G8+抖音!G8+PDD!G8+得物!G8+京东自营财经口径!G8+京东POP财经口径!G8+'视频号+官网+小程序'!G8+快手!G8+唯品会!G8+'线下门店-直营'!G8++'线下门店-经销'!G8+线下渠道!G8+淘系达播!G8+抖音达播!G8 -> 48293320 | I8: =淘系!H8+抖音!H8+PDD!H8+得物!H8+京东自营财经口径!H8+京东POP财经口径!H8+'视频号+官网+小程序'!H8+快手!H8+唯品会!H8+'线下门店-直营'!H8++'线下门店-经销'!H8+线下渠道!H8+淘系达播!H8+抖音达播!H8 -> 43922618 | J8: =淘系!I8+抖音!I8+PDD!I8+得物!I8+京东自营财经口径!I8+京东POP财经口径!I8+'视频号+官网+小程序'!I8+快手!I8+唯品会!I8+'线下门店-直营'!I8++'线下门店-经销'!I8+线下渠道!I8+淘系达播!I8+抖音达播!I8 -> 30673968 | K8: =淘系!J8+抖音!J8+PDD!J8+得物!J8+京东自营财经口径!J8+京东POP财经口径!J8+'视频号+官网+小程序'!J8+快手!J8+唯品会!J8+'线下门店-直营'!J8++'线下门店-经销'!J8+线下渠道!J8+淘系达播!J8+抖音达播!J8 -> 42465045 | L8: =淘系!K8+抖音!K8+PDD!K8+得物!K8+京东自营财经口径!K8+京东POP财经口径!K8+'视频号+官网+小程序'!K8+快手!K8+唯品会!K8+'线下门店-直营'!K8++'线下门店-经销'!K8+线下渠道!K8+淘系达播!K8+抖音达播!K8 -> 31058310 | ... O8: =淘系!N8+抖音!N8+PDD!N8+得物!N8+京东自营财经口径!N8+京东POP财经口径!N8+'视频号+官网+小程序'!N8+快手!N8+唯品会!N8+'线下门店-直营'!N8++'线下门店-经销'!N8+线下渠道!N8+淘系达播!N8+抖音达播!N8 -> 42115074 | P8: =SUM(C8:O8) -> 4.5654745e+08 | R8: 渠道填写
B10: 零售价（去除退货后的） | C10: =淘系!C10+抖音!C10+PDD!C10+得物!C10+京东自营财经口径!C10+京东POP财经口径!C10+'视频号+官网+小程序'!C10+快手!C10+唯品会!C10+'线下门店-直营'!C10++'线下门店-经销'!C10+线下渠道!C10+淘系达播!C10+抖音达播!C10 -> 43169030 | E10: =淘系!D10+抖音!D10+PDD!D10+得物!D10+京东自营财经口径!D10+京东POP财经口径!D10+'视频号+官网+小程序'!D10+快手!D10+唯品会!D10+'线下门店-直营'!D10++'线下门店-经销'!D10+线下渠道!D10+淘系达播!D10+抖音达播!D10 -> 41319765 | F10: =淘系!E10+抖音!E10+PDD!E10+得物!E10+京东自营财经口径!E10+京东POP财经口径!E10+'视频号+官网+小程序'!E10+快手!E10+唯品会!E10+'线下门店-直营'!E10++'线下门店-经销'!E10+线下渠道!E10+淘系达播!E10+抖音达播!E10 -> 34649173 | G10: =淘系!F10+抖音!F10+PDD!F10+得物!F10+京东自营财经口径!F10+京东POP财经口径!F10+'视频号+官网+小程序'!F10+快手!F10+唯品会!F10+'线下门店-直营'!F10++'线下门店-经销'!F10+线下渠道!F10+淘系达播!F10+抖音达播!F10 -> 30349389 | H10: =淘系!G10+抖音!G10+PDD!G10+得物!G10+京东自营财经口径!G10+京东POP财经口径!G10+'视频号+官网+小程序'!G10+快手!G10+唯品会!G10+'线下门店-直营'!G10++'线下门店-经销'!G10+线下渠道!G10+淘系达播!G10+抖音达播!G10 -> 62773132 | I10: =淘系!H10+抖音!H10+PDD!H10+得物!H10+京东自营财经口径!H10+京东POP财经口径!H10+'视频号+官网+小程序'!H10+快手!H10+唯品会!H10+'线下门店-直营'!H10++'线下门店-经销'!H10+线下渠道!H10+淘系达播!H10+抖音达播!H10 -> 57311536 | J10: =淘系!I10+抖音!I10+PDD!I10+得物!I10+京东自营财经口径!I10+京东POP财经口径!I10+'视频号+官网+小程序'!I10+快手!I10+唯品会!I10+'线下门店-直营'!I10++'线下门店-经销'!I10+线下渠道!I10+淘系达播!I10+抖音达播!I10 -> 40240744 | K10: =淘系!J10+抖音!J10+PDD!J10+得物!J10+京东自营财经口径!J10+京东POP财经口径!J10+'视频号+官网+小程序'!J10+快手!J10+唯品会!J10+'线下门店-直营'!J10++'线下门店-经销'!J10+线下渠道!J10+淘系达播!J10+抖音达播!J10 -> 55453830 | L10: =淘系!K10+抖音!K10+PDD!K10+得物!K10+京东自营财经口径!K10+京东POP财经口径!K10+'视频号+官网+小程序'!K10+快手!K10+唯品会!K10+'线下门店-直营'!K10++'线下门店-经销'!K10+线下渠道!K10+淘系达播!K10+抖音达播!K10 -> 40718429 | ... O10: =淘系!N10+抖音!N10+PDD!N10+得物!N10+京东自营财经口径!N10+京东POP财经口径!N10+'视频号+官网+小程序'!N10+快手!N10+唯品会!N10+'线下门店-直营'!N10++'线下门店-经销'!N10+线下渠道!N10+淘系达播!N10+抖音达播!N10 -> 55451705 | P10: =SUM(C10:O10) -> 5.9951799e+08 | R10: 渠道第二次填写
B11: 合同折扣及返利 (线下） | C11: =淘系!C11+抖音!C11+PDD!C11+得物!C11+京东自营财经口径!C11+京东POP财经口径!C11+'视频号+官网+小程序'!C11+快手!C11+唯品会!C11+'线下门店-直营'!C11+'线下门店-经销'!C11+线下渠道!C11+淘系达播!C11+抖音达播!C11 -> 1195159.2 | E11: =淘系!D11+抖音!D11+PDD!D11+得物!D11+京东自营财经口径!D11+京东POP财经口径!D11+'视频号+官网+小程序'!D11+快手!D11+唯品会!D11+'线下门店-直营'!D11+'线下门店-经销'!D11+线下渠道!D11+淘系达播!D11+抖音达播!D11 -> 1300782.2 | F11: =淘系!E11+抖音!E11+PDD!E11+得物!E11+京东自营财经口径!E11+京东POP财经口径!E11+'视频号+官网+小程序'!E11+快手!E11+唯品会!E11+'线下门店-直营'!E11+'线下门店-经销'!E11+线下渠道!E11+淘系达播!E11+抖音达播!E11 -> 1017203.9 | G11: =淘系!F11+抖音!F11+PDD!F11+得物!F11+京东自营财经口径!F11+京东POP财经口径!F11+'视频号+官网+小程序'!F11+快手!F11+唯品会!F11+'线下门店-直营'!F11+'线下门店-经销'!F11+线下渠道!F11+淘系达播!F11+抖音达播!F11 -> 947622.99 | H11: =淘系!G11+抖音!G11+PDD!G11+得物!G11+京东自营财经口径!G11+京东POP财经口径!G11+'视频号+官网+小程序'!G11+快手!G11+唯品会!G11+'线下门店-直营'!G11+'线下门店-经销'!G11+线下渠道!G11+淘系达播!G11+抖音达播!G11 -> 1706368.4 | I11: =淘系!H11+抖音!H11+PDD!H11+得物!H11+京东自营财经口径!H11+京东POP财经口径!H11+'视频号+官网+小程序'!H11+快手!H11+唯品会!H11+'线下门店-直营'!H11+'线下门店-经销'!H11+线下渠道!H11+淘系达播!H11+抖音达播!H11 -> 1674116.6 | J11: =淘系!I11+抖音!I11+PDD!I11+得物!I11+京东自营财经口径!I11+京东POP财经口径!I11+'视频号+官网+小程序'!I11+快手!I11+唯品会!I11+'线下门店-直营'!I11+'线下门店-经销'!I11+线下渠道!I11+淘系达播!I11+抖音达播!I11 -> 1317289.2 | K11: =淘系!J11+抖音!J11+PDD!J11+得物!J11+京东自营财经口径!J11+京东POP财经口径!J11+'视频号+官网+小程序'!J11+快手!J11+唯品会!J11+'线下门店-直营'!J11+'线下门店-经销'!J11+线下渠道!J11+淘系达播!J11+抖音达播!J11 -> 1660136.2 | L11: =淘系!K11+抖音!K11+PDD!K11+得物!K11+京东自营财经口径!K11+京东POP财经口径!K11+'视频号+官网+小程序'!K11+快手!K11+唯品会!K11+'线下门店-直营'!K11+'线下门店-经销'!K11+线下渠道!K11+淘系达播!K11+抖音达播!K11 -> 1299971.8 | ... O11: =淘系!N11+抖音!N11+PDD!N11+得物!N11+京东自营财经口径!N11+京东POP财经口径!N11+'视频号+官网+小程序'!N11+快手!N11+唯品会!N11+'线下门店-直营'!N11+'线下门店-经销'!N11+线下渠道!N11+淘系达播!N11+抖音达播!N11 -> 2086010.3 | P11: =SUM(C11:O11) -> 18348907 | Q11: =P11/P8 -> 0.040190581 | R11: 线下渠道填写 | S11: =P11/$P$10 -> 0.030606099
B12: 国补自补 （线上） | C12: =淘系!C12+抖音!C12+PDD!C12+得物!C12+京东自营财经口径!C12+京东POP财经口径!C12+'视频号+官网+小程序'!C12+快手!C12+唯品会!C12+'线下门店-直营'!C12+'线下门店-经销'!C12+线下渠道!C12+淘系达播!C12+抖音达播!C12 -> 3374204.7 | E12: =淘系!D12+抖音!D12+PDD!D12+得物!D12+京东自营财经口径!D12+京东POP财经口径!D12+'视频号+官网+小程序'!D12+快手!D12+唯品会!D12+'线下门店-直营'!D12+'线下门店-经销'!D12+线下渠道!D12+淘系达播!D12+抖音达播!D12 -> 3225504 | F12: =淘系!E12+抖音!E12+PDD!E12+得物!E12+京东自营财经口径!E12+京东POP财经口径!E12+'视频号+官网+小程序'!E12+快手!E12+唯品会!E12+'线下门店-直营'!E12+'线下门店-经销'!E12+线下渠道!E12+淘系达播!E12+抖音达播!E12 -> 2793045.8 | G12: =淘系!F12+抖音!F12+PDD!F12+得物!F12+京东自营财经口径!F12+京东POP财经口径!F12+'视频号+官网+小程序'!F12+快手!F12+唯品会!F12+'线下门店-直营'!F12+'线下门店-经销'!F12+线下渠道!F12+淘系达播!F12+抖音达播!F12 -> 2421445.1 | H12: =淘系!G12+抖音!G12+PDD!G12+得物!G12+京东自营财经口径!G12+京东POP财经口径!G12+'视频号+官网+小程序'!G12+快手!G12+唯品会!G12+'线下门店-直营'!G12+'线下门店-经销'!G12+线下渠道!G12+淘系达播!G12+抖音达播!G12 -> 5483400.1 | I12: =淘系!H12+抖音!H12+PDD!H12+得物!H12+京东自营财经口径!H12+京东POP财经口径!H12+'视频号+官网+小程序'!H12+快手!H12+唯品会!H12+'线下门店-直营'!H12+'线下门店-经销'!H12+线下渠道!H12+淘系达播!H12+抖音达播!H12 -> 4885124.8 | J12: =淘系!I12+抖音!I12+PDD!I12+得物!I12+京东自营财经口径!I12+京东POP财经口径!I12+'视频号+官网+小程序'!I12+快手!I12+唯品会!I12+'线下门店-直营'!I12+'线下门店-经销'!I12+线下渠道!I12+淘系达播!I12+抖音达播!I12 -> 3103718.8 | K12: =淘系!J12+抖音!J12+PDD!J12+得物!J12+京东自营财经口径!J12+京东POP财经口径!J12+'视频号+官网+小程序'!J12+快手!J12+唯品会!J12+'线下门店-直营'!J12+'线下门店-经销'!J12+线下渠道!J12+淘系达播!J12+抖音达播!J12 -> 4576920.8 | L12: =淘系!K12+抖音!K12+PDD!K12+得物!K12+京东自营财经口径!K12+京东POP财经口径!K12+'视频号+官网+小程序'!K12+快手!K12+唯品会!K12+'线下门店-直营'!K12+'线下门店-经销'!K12+线下渠道!K12+淘系达播!K12+抖音达播!K12 -> 3197466.3 | ... O12: =淘系!N12+抖音!N12+PDD!N12+得物!N12+京东自营财经口径!N12+京东POP财经口径!N12+'视频号+官网+小程序'!N12+快手!N12+唯品会!N12+'线下门店-直营'!N12+'线下门店-经销'!N12+线下渠道!N12+淘系达播!N12+抖音达播!N12 -> 4234950.4 | P12: =SUM(C12:O12) -> 48800085 | Q12: =P12/P8 -> 0.1068894 | R12: 渠道填写 | S12: =P12/$P$10 -> 0.081398866
B13: 红包消费券等促销折扣 | C13: =淘系!C13+抖音!C13+PDD!C13+得物!C13+京东自营财经口径!C13+京东POP财经口径!C13+'视频号+官网+小程序'!C13+快手!C13+唯品会!C13+'线下门店-直营'!C13+'线下门店-经销'!C13+线下渠道!C13+淘系达播!C13+抖音达播!C13 -> 7394578.7 | E13: =淘系!D13+抖音!D13+PDD!D13+得物!D13+京东自营财经口径!D13+京东POP财经口径!D13+'视频号+官网+小程序'!D13+快手!D13+唯品会!D13+'线下门店-直营'!D13+'线下门店-经销'!D13+线下渠道!D13+淘系达播!D13+抖音达播!D13 -> 5584980.1 | F13: =淘系!E13+抖音!E13+PDD!E13+得物!E13+京东自营财经口径!E13+京东POP财经口径!E13+'视频号+官网+小程序'!E13+快手!E13+唯品会!E13+'线下门店-直营'!E13+'线下门店-经销'!E13+线下渠道!E13+淘系达播!E13+抖音达播!E13 -> 4178396.9 | G13: =淘系!F13+抖音!F13+PDD!F13+得物!F13+京东自营财经口径!F13+京东POP财经口径!F13+'视频号+官网+小程序'!F13+快手!F13+唯品会!F13+'线下门店-直营'!F13+'线下门店-经销'!F13+线下渠道!F13+淘系达播!F13+抖音达播!F13 -> 3877961.3 | H13: =淘系!G13+抖音!G13+PDD!G13+得物!G13+京东自营财经口径!G13+京东POP财经口径!G13+'视频号+官网+小程序'!G13+快手!G13+唯品会!G13+'线下门店-直营'!G13+'线下门店-经销'!G13+线下渠道!G13+淘系达播!G13+抖音达播!G13 -> 7290043.5 | I13: =淘系!H13+抖音!H13+PDD!H13+得物!H13+京东自营财经口径!H13+京东POP财经口径!H13+'视频号+官网+小程序'!H13+快手!H13+唯品会!H13+'线下门店-直营'!H13+'线下门店-经销'!H13+线下渠道!H13+淘系达播!H13+抖音达播!H13 -> 6829676.2 | J13: =淘系!I13+抖音!I13+PDD!I13+得物!I13+京东自营财经口径!I13+京东POP财经口径!I13+'视频号+官网+小程序'!I13+快手!I13+唯品会!I13+'线下门店-直营'!I13+'线下门店-经销'!I13+线下渠道!I13+淘系达播!I13+抖音达播!I13 -> 5145768 | K13: =淘系!J13+抖音!J13+PDD!J13+得物!J13+京东自营财经口径!J13+京东POP财经口径!J13+'视频号+官网+小程序'!J13+快手!J13+唯品会!J13+'线下门店-直营'!J13+'线下门店-经销'!J13+线下渠道!J13+淘系达播!J13+抖音达播!J13 -> 6751727.9 | L13: =淘系!K13+抖音!K13+PDD!K13+得物!K13+京东自营财经口径!K13+京东POP财经口径!K13+'视频号+官网+小程序'!K13+快手!K13+唯品会!K13+'线下门店-直营'!K13+'线下门店-经销'!K13+线下渠道!K13+淘系达播!K13+抖音达播!K13 -> 5162680.5 | ... O13: =淘系!N13+抖音!N13+PDD!N13+得物!N13+京东自营财经口径!N13+京东POP财经口径!N13+'视频号+官网+小程序'!N13+快手!N13+唯品会!N13+'线下门店-直营'!N13+'线下门店-经销'!N13+线下渠道!N13+淘系达播!N13+抖音达播!N13 -> 7015669.9 | P13: =SUM(C13:O13) -> 75821557 | Q13: =P13/P8 -> 0.16607596 | R13: 渠道填写 | S13: =P13/$P$10 -> 0.12647086
B14: TTL 折扣合计 | C14: =SUM(C11:C13) -> 11963943 | E14: =SUM(E11:E13) -> 10111266 | F14: =SUM(F11:F13) -> 7988646.6 | G14: =SUM(G11:G13) -> 7247029.4 | H14: =SUM(H11:H13) -> 14479812 | I14: =SUM(I11:I13) -> 13388918 | J14: =SUM(J11:J13) -> 9566775.9 | K14: =SUM(K11:K13) -> 12988785 | L14: =SUM(L11:L13) -> 9660118.5 | ... O14: =SUM(O11:O13) -> 13336631 | P14: =SUM(C14:O14) -> 1.4297055e+08 | Q14: =P14/P8 -> 0.31315595 | S14: =P14/$P$10 -> 0.23847583
B15: GSV | C15: =C8 -> 31205088 | E15: =E8 -> 31208498 | F15: =F8 -> 26660526 | G15: =G8 -> 23102360 | H15: =H8 -> 48293320 | I15: =I8 -> 43922618 | J15: =J8 -> 30673968 | K15: =K8 -> 42465045 | L15: =L8 -> 31058310 | ... O15: =O8 -> 42115074 | P15: =SUM(C15:O15) -> 4.5654745e+08
B16: 营业收入 | C16: =+C8/1.13 -> 27615122 | E16: =+E8/1.13 -> 27618140 | F16: =+F8/1.13 -> 23593386 | G16: =+G8/1.13 -> 20444566 | H16: =+H8/1.13 -> 42737451 | I16: =+I8/1.13 -> 38869573 | J16: =+J8/1.13 -> 27145104 | K16: =+K8/1.13 -> 37579685 | L16: =+L8/1.13 -> 27485230 | ... O16: =+O8/1.13 -> 37269977 | P16: =SUM(C16:O16) -> 4.0402429e+08 | U16: =P16-淘系!O16-淘系达播!O16-抖音!O16-抖音达播!O16-快手!O16-京东POP财经口径!O16-京东自营财经口径!O16-PDD!O16-得物!O16-'视频号+官网+小程序'!O16-唯品会!O16-'线下门店-直营'!O16-'线下门店-经销'!O16-线下渠道!O16 -> 0
C17: =C14/C15 -> 0.38339718 | U17: =P17-淘系!O17-淘系达播!O17-抖音!O17-抖音达播!O17-快手!O17-京东POP财经口径!O17-京东自营财经口径!O17-PDD!O17-得物!O17-'视频号+官网+小程序'!O17-唯品会!O17-'线下门店-直营'!O17-'线下门店-经销'!O17-线下渠道!O17 -> 0
